Workbook

Sheet Gerenciamento
B2: Observação | C2: N° | D2: Resultado | E2: Investimento | F2: Retorno | G2: Capital Atual | I2: =IF(algoritmo!L4=1,"% Micro Serie","% Acerto") -> % Acerto | J2: =IF(algoritmo!L4=1,"Riparti Qui","Erros aceitos") -> Erros aceitos | K2: =IF(#REF!="Progressivo","€➔Prelievo","Ever") -> #REF! | L2: =IF(#REF!="Progressivo","Prelievo","Green") -> #REF!
C3: 1 | D3: W | E3: =IFERROR(algoritmo!C3,"") -> 10 | F3: =IFERROR(IF(algoritmo!D3=0,-E3,algoritmo!D3),"") -> 10 | G3: =IFERROR(algoritmo!F3,"") -> 210 | H3: =IF(J3="◄◄","↑","") | I3: =IFERROR(algoritmo!J3,"") -> 1 | J3: =IF(G3="","",IF(algoritmo!$L$4=1,IF(algoritmo!F3>=algoritmo!G2,"◄◄",""),IF(algoritmo!I2+algoritmo!B3=$O$14,"Ciclo com Lucro",IF(algoritmo!H3=$O$13-$O$14+1,"Ciclo com Perda",""&($O$13-$O$14-algoritmo!H3)&"")))) -> 5 | K3: =IF(#REF!="Progressivo",algoritmo!E3,"") -> #REF! | L3: =IF(#REF!="Progressivo",IF(K3="","",K3),"") -> #REF!
C4: =IF(C3<$O$13,C3+1,IF(D3=""," ",C3+1)) -> 2 | D4: L | E4: =IFERROR(algoritmo!C4,"") -> 3.3333333 | F4: =IFERROR(IF(algoritmo!D4=0,-E4,algoritmo!D4),"") -> -3.3333333 | G4: =IFERROR(algoritmo!F4,"") -> 206.66667 | H4: =IF(J4="◄◄","↑","") | I4: =IFERROR(algoritmo!J4,"") -> 0.5 | J4: =IF(G4="","",IF(algoritmo!$L$4=1,IF(algoritmo!F4>=algoritmo!G3,"◄◄",""),IF(algoritmo!I3+algoritmo!B4=$O$14,"Ciclo com Lucro",IF(algoritmo!H4=$O$13-$O$14+1,"Ciclo com Perda",""&($O$13-$O$14-algoritmo!H4)&"")))) -> 4 | K4: =IF(#REF!="Progressivo",algoritmo!E4,"") -> #REF! | L4: =IF(#REF!="Progressivo",IF(K4="","",K4),"") -> #REF!
C5: =IF(C4<$O$13,C4+1,IF(D4=""," ",C4+1)) -> 3 | E5: =IFERROR(algoritmo!C5,"") -> 6.6666667 | F5: =IFERROR(IF(algoritmo!D5=0,-E5,algoritmo!D5),"") | G5: =IFERROR(algoritmo!F5,"") | H5: =IF(J5="◄◄","↑","") | I5: =IFERROR(algoritmo!J5,"") | J5: =IF(G5="","",IF(algoritmo!$L$4=1,IF(algoritmo!F5>=algoritmo!G4,"◄◄",""),IF(algoritmo!I4+algoritmo!B5=$O$14,"Ciclo com Lucro",IF(algoritmo!H5=$O$13-$O$14+1,"Ciclo com Perda"," "&($O$13-$O$14-algoritmo!H5)&"")))) | K5: =IF(#REF!="Progressivo",algoritmo!E5,"") -> #REF! | L5: =IF(#REF!="Progressivo",IF(K5="","",K5),"") -> #REF!
C6: =IF(C5<$O$13,C5+1,IF(D5=""," ",C5+1)) -> 4 | E6: =IFERROR(algoritmo!C6,"") | F6: =IFERROR(IF(algoritmo!D6=0,-E6,algoritmo!D6),"") | G6: =IFERROR(algoritmo!F6,"") | H6: =IF(J6="◄◄","↑","") | I6: =IFERROR(algoritmo!J6,"") | J6: =IF(G6="","",IF(algoritmo!$L$4=1,IF(algoritmo!F6>=algoritmo!G5,"◄◄",""),IF(algoritmo!I5+algoritmo!B6=$O$14,"Ciclo com Lucro",IF(algoritmo!H6=$O$13-$O$14+1,"Ciclo com Perda"," "&($O$13-$O$14-algoritmo!H6)&"")))) | K6: =IF(#REF!="Progressivo",algoritmo!E6,"") -> #REF! | L6: =IF(#REF!="Progressivo",IF(K6="","",K6),"") -> #REF!
C7: =IF(C6<$O$13,C6+1,IF(D6=""," ",C6+1)) -> 5 | E7: =IFERROR(algoritmo!C7,"") | F7: =IFERROR(IF(algoritmo!D7=0,-E7,algoritmo!D7),"") | G7: =IFERROR(algoritmo!F7,"") | H7: =IF(J7="◄◄","↑","") | I7: =IFERROR(algoritmo!J7,"") | J7: =IF(G7="","",IF(algoritmo!$L$4=1,IF(algoritmo!F7>=algoritmo!G6,"◄◄",""),IF(algoritmo!I6+algoritmo!B7=$O$14,"Ciclo com Lucro",IF(algoritmo!H7=$O$13-$O$14+1,"Ciclo com Perda"," "&($O$13-$O$14-algoritmo!H7)&"")))) | K7: =IF(#REF!="Progressivo",algoritmo!E7,"") -> #REF! | L7: =IF(#REF!="Progressivo",IF(K7="","",K7),"") -> #REF!
C8: =IF(C7<$O$13,C7+1,IF(D7=""," ",C7+1)) -> 6 | E8: =IFERROR(algoritmo!C8,"") | F8: =IFERROR(IF(algoritmo!D8=0,-E8,algoritmo!D8),"") | G8: =IFERROR(algoritmo!F8,"") | H8: =IF(J8="◄◄","↑","") | I8: =IFERROR(algoritmo!J8,"") | J8: =IF(G8="","",IF(algoritmo!$L$4=1,IF(algoritmo!F8>=algoritmo!G7,"◄◄",""),IF(algoritmo!I7+algoritmo!B8=$O$14,"Ciclo com Lucro",IF(algoritmo!H8=$O$13-$O$14+1,"Ciclo com Perda"," "&($O$13-$O$14-algoritmo!H8)&"")))) | K8: =IF(#REF!="Progressivo",algoritmo!E8,"") -> #REF! | L8: =IF(#REF!="Progressivo",IF(K8="","",K8),"") -> #REF!
C9: =IF(C8<$O$13,C8+1,IF(D8=""," ",C8+1)) -> 7 | E9: =IFERROR(algoritmo!C9,"") | F9: =IFERROR(IF(algoritmo!D9=0,-E9,algoritmo!D9),"") | G9: =IFERROR(algoritmo!F9,"") | H9: =IF(J9="◄◄","↑","") | I9: =IFERROR(algoritmo!J9,"") | J9: =IF(G9="","",IF(algoritmo!$L$4=1,IF(algoritmo!F9>=algoritmo!G8,"◄◄",""),IF(algoritmo!I8+algoritmo!B9=$O$14,"Ciclo com Lucro",IF(algoritmo!H9=$O$13-$O$14+1,"Ciclo com Perda"," "&($O$13-$O$14-algoritmo!H9)&"")))) | K9: =IF(#REF!="Progressivo",algoritmo!E9,"") -> #REF! | L9: =IF(#REF!="Progressivo",IF(K9="","",K9),"") -> #REF! | N9: Gerenciamento Masaniello BotCloud
C10: =IF(C9<$O$13,C9+1,IF(D9=""," ",C9+1)) | E10: =IFERROR(algoritmo!C10,"") | F10: =IFERROR(IF(algoritmo!D10=0,-E10,algoritmo!D10),"") | G10: =IFERROR(algoritmo!F10,"") | H10: =IF(J10="◄◄","↑","") | I10: =IFERROR(algoritmo!J10,"") | J10: =IF(G10="","",IF(algoritmo!$L$4=1,IF(algoritmo!F10>=algoritmo!G9,"◄◄",""),IF(algoritmo!I9+algoritmo!B10=$O$14,"Ciclo com Lucro",IF(algoritmo!H10=$O$13-$O$14+1,"Ciclo com Perda"," "&($O$13-$O$14-algoritmo!H10)&"")))) | K10: =IF(#REF!="Progressivo",algoritmo!E10,"") -> #REF! | L10: =IF(#REF!="Progressivo",IF(K10="","",K10),"") -> #REF!
C11: =IF(C10<$O$13,C10+1,IF(D10=""," ",C10+1)) | E11: =IFERROR(algoritmo!C11,"") | F11: =IFERROR(IF(algoritmo!D11=0,-E11,algoritmo!D11),"") | G11: =IFERROR(algoritmo!F11,"") | H11: =IF(J11="◄◄","↑","") | I11: =IFERROR(algoritmo!J11,"") | J11: =IF(G11="","",IF(algoritmo!$L$4=1,IF(algoritmo!F11>=algoritmo!G10,"◄◄",""),IF(algoritmo!I10+algoritmo!B11=$O$14,"Ciclo com Lucro",IF(algoritmo!H11=$O$13-$O$14+1,"Ciclo com Perda"," "&($O$13-$O$14-algoritmo!H11)&"")))) | K11: =IF(#REF!="Progressivo",algoritmo!E11,"") -> #REF! | L11: =IF(#REF!="Progressivo",IF(K11="","",K11),"") -> #REF! | N11: Configurar Gerenciamento
C12: =IF(C11<$O$13,C11+1,IF(D11=""," ",C11+1)) | E12: =IFERROR(algoritmo!C12,"") | F12: =IFERROR(IF(algoritmo!D12=0,-E12,algoritmo!D12),"") | G12: =IFERROR(algoritmo!F12,"") | H12: =IF(J12="◄◄","↑","") | I12: =IFERROR(algoritmo!J12,"") | J12: =IF(G12="","",IF(algoritmo!$L$4=1,IF(algoritmo!F12>=algoritmo!G11,"◄◄",""),IF(algoritmo!I11+algoritmo!B12=$O$14,"Ciclo com Lucro",IF(algoritmo!H12=$O$13-$O$14+1,"Ciclo com Perda"," "&($O$13-$O$14-algoritmo!H12)&"")))) | K12: =IF(#REF!="Progressivo",algoritmo!E12,"") -> #REF! | L12: =IF(#REF!="Progressivo",IF(K12="","",K12),"") -> #REF! | N12: Capital investido | O12: 200
C13: =IF(C12<$O$13,C12+1,IF(D12=""," ",C12+1)) | E13: =IFERROR(algoritmo!C13,"") | F13: =IFERROR(IF(algoritmo!D13=0,-E13,algoritmo!D13),"") | G13: =IFERROR(algoritmo!F13,"") | H13: =IF(J13="◄◄","↑","") | I13: =IFERROR(algoritmo!J13,"") | J13: =IF(G13="","",IF(algoritmo!$L$4=1,IF(algoritmo!F13>=algoritmo!G12,"◄◄",""),IF(algoritmo!I12+algoritmo!B13=$O$14,"Ciclo com Lucro",IF(algoritmo!H13=$O$13-$O$14+1,"Ciclo com Perda"," "&($O$13-$O$14-algoritmo!H13)&"")))) | K13: =IF(#REF!="Progressivo",algoritmo!E13,"") -> #REF! | L13: =IF(#REF!="Progressivo",IF(K13="","",K13),"") -> #REF! | N13: Operações totais | O13: 7
C14: =IF(C13<$O$13,C13+1,IF(D13=""," ",C13+1)) | E14: =IFERROR(algoritmo!C14,"") | F14: =IFERROR(IF(algoritmo!D14=0,-E14,algoritmo!D14),"") | G14: =IFERROR(algoritmo!F14,"") | H14: =IF(J14="◄◄","↑","") | I14: =IFERROR(algoritmo!J14,"") | J14: =IF(G14="","",IF(algoritmo!$L$4=1,IF(algoritmo!F14>=algoritmo!G13,"◄◄",""),IF(algoritmo!I13+algoritmo!B14=$O$14,"Ciclo com Lucro",IF(algoritmo!H14=$O$13-$O$14+1,"Ciclo com Perda"," "&($O$13-$O$14-algoritmo!H14)&"")))) | K14: =IF(#REF!="Progressivo",algoritmo!E14,"") -> #REF! | L14: =IF(#REF!="Progressivo",IF(K14="","",K14),"") -> #REF! | N14: Vitórias | O14: 2 | P14: =O14/O13 -> 0.28571429
C15: =IF(C14<$O$13,C14+1,IF(D14=""," ",C14+1)) | E15: =IFERROR(algoritmo!C15,"") | F15: =IFERROR(IF(algoritmo!D15=0,-E15,algoritmo!D15),"") | G15: =IFERROR(algoritmo!F15,"") | H15: =IF(J15="◄◄","↑","") | I15: =IFERROR(algoritmo!J15,"") | J15: =IF(G15="","",IF(algoritmo!$L$4=1,IF(algoritmo!F15>=algoritmo!G14,"◄◄",""),IF(algoritmo!I14+algoritmo!B15=$O$14,"Ciclo com Lucro",IF(algoritmo!H15=$O$13-$O$14+1,"Ciclo com Perda"," "&($O$13-$O$14-algoritmo!H15)&"")))) | K15: =IF(#REF!="Progressivo",algoritmo!E15,"") -> #REF! | L15: =IF(#REF!="Progressivo",IF(K15="","",K15),"") -> #REF! | N15: Payout | O15: 2
C16: =IF(C15<$O$13,C15+1,IF(D15=""," ",C15+1)) | E16: =IFERROR(algoritmo!C16,"") | F16: =IFERROR(IF(algoritmo!D16=0,-E16,algoritmo!D16),"") | G16: =IFERROR(algoritmo!F16,"") | H16: =IF(J16="◄◄","↑","") | I16: =IFERROR(algoritmo!J16,"") | J16: =IF(G16="","",IF(algoritmo!$L$4=1,IF(algoritmo!F16>=algoritmo!G15,"◄◄",""),IF(algoritmo!I15+algoritmo!B16=$O$14,"Ciclo com Lucro",IF(algoritmo!H16=$O$13-$O$14+1,"Ciclo com Perda"," "&($O$13-$O$14-algoritmo!H16)&"")))) | K16: =IF(#REF!="Progressivo",algoritmo!E16,"") -> #REF! | L16: =IF(#REF!="Progressivo",IF(K16="","",K16),"") -> #REF! | N16: Modo | O16: Normal
C17: =IF(C16<$O$13,C16+1,IF(D16=""," ",C16+1)) | E17: =IFERROR(algoritmo!C17,"") | F17: =IFERROR(IF(algoritmo!D17=0,-E17,algoritmo!D17),"") | G17: =IFERROR(algoritmo!F17,"") | H17: =IF(J17="◄◄","↑","") | I17: =IFERROR(algoritmo!J17,"") | J17: =IF(G17="","",IF(algoritmo!$L$4=1,IF(algoritmo!F17>=algoritmo!G16,"◄◄",""),IF(algoritmo!I16+algoritmo!B17=$O$14,"Ciclo com Lucro",IF(algoritmo!H17=$O$13-$O$14+1,"Ciclo com Perda"," "&($O$13-$O$14-algoritmo!H17)&"")))) | K17: =IF(#REF!="Progressivo",algoritmo!E17,"") -> #REF! | L17: =IF(#REF!="Progressivo",IF(K17="","",K17),"") -> #REF!
C18: =IF(C17<$O$13,C17+1,IF(D17=""," ",C17+1)) | E18: =IFERROR(algoritmo!C18,"") | F18: =IFERROR(IF(algoritmo!D18=0,-E18,algoritmo!D18),"") | G18: =IFERROR(algoritmo!F18,"") | H18: =IF(J18="◄◄","↑","") | I18: =IFERROR(algoritmo!J18,"") | J18: =IF(G18="","",IF(algoritmo!$L$4=1,IF(algoritmo!F18>=algoritmo!G17,"◄◄",""),IF(algoritmo!I17+algoritmo!B18=$O$14,"Ciclo com Lucro",IF(algoritmo!H18=$O$13-$O$14+1,"Ciclo com Perda"," "&($O$13-$O$14-algoritmo!H18)&"")))) | K18: =IF(#REF!="Progressivo",algoritmo!E18,"") -> #REF! | L18: =IF(#REF!="Progressivo",IF(K18="","",K18),"") -> #REF! | N18: Resultado a ser atingido
C19: =IF(C18<$O$13,C18+1,IF(D18=""," ",C18+1)) | E19: =IFERROR(algoritmo!C19,"") | F19: =IFERROR(IF(algoritmo!D19=0,-E19,algoritmo!D19),"") | G19: =IFERROR(algoritmo!F19,"") | H19: =IF(J19="◄◄","↑","") | I19: =IFERROR(algoritmo!J19,"") | J19: =IF(G19="","",IF(algoritmo!$L$4=1,IF(algoritmo!F19>=algoritmo!G18,"◄◄",""),IF(algoritmo!I18+algoritmo!B19=$O$14,"Ciclo com Lucro",IF(algoritmo!H19=$O$13-$O$14+1,"Ciclo com Perda"," "&($O$13-$O$14-algoritmo!H19)&"")))) | K19: =IF(#REF!="Progressivo",algoritmo!E19,"") -> #REF! | L19: =IF(#REF!="Progressivo",IF(K19="","",K19),"") -> #REF! | N19: Resultado esperado R$ | O19: =O12*(1+O20)^(1+COUNTIF(J3:J102,"hai vinto")) -> 213.33333
C20: =IF(C19<$O$13,C19+1,IF(D19=""," ",C19+1)) | E20: =IFERROR(algoritmo!C20,"") | F20: =IFERROR(IF(algoritmo!D20=0,-E20,algoritmo!D20),"") | G20: =IFERROR(algoritmo!F20,"") | H20: =IF(J20="◄◄","↑","") | I20: =IFERROR(algoritmo!J20,"") | J20: =IF(G20="","",IF(algoritmo!$L$4=1,IF(algoritmo!F20>=algoritmo!G19,"◄◄",""),IF(algoritmo!I19+algoritmo!B20=$O$14,"Ciclo com Lucro",IF(algoritmo!H20=$O$13-$O$14+1,"Ciclo com Perda"," "&($O$13-$O$14-algoritmo!H20)&"")))) | K20: =IF(#REF!="Progressivo",algoritmo!E20,"") -> #REF! | L20: =IF(#REF!="Progressivo",IF(K20="","",K20),"") -> #REF! | N20: Resultado esperado % | O20: =algoritmo!$N$2-1 -> 0.066666667
C21: =IF(C20<$O$13,C20+1,IF(D20=""," ",C20+1)) | E21: =IFERROR(algoritmo!C21,"") | F21: =IFERROR(IF(algoritmo!D21=0,-E21,algoritmo!D21),"") | G21: =IFERROR(algoritmo!F21,"") | H21: =IF(J21="◄◄","↑","") | I21: =IFERROR(algoritmo!J21,"") | J21: =IF(G21="","",IF(algoritmo!$L$4=1,IF(algoritmo!F21>=algoritmo!G20,"◄◄",""),IF(algoritmo!I20+algoritmo!B21=$O$14,"Ciclo com Lucro",IF(algoritmo!H21=$O$13-$O$14+1,"Ciclo com Perda"," "&($O$13-$O$14-algoritmo!H21)&"")))) | K21: =IF(#REF!="Progressivo",algoritmo!E21,"") -> #REF! | L21: =IF(#REF!="Progressivo",IF(K21="","",K21),"") -> #REF! | N21: Stop Win recomendado | O21: =O19-O12 -> 13.333333
C22: =IF(C21<$O$13,C21+1,IF(D21=""," ",C21+1)) | E22: =IFERROR(algoritmo!C22,"") | F22: =IFERROR(IF(algoritmo!D22=0,-E22,algoritmo!D22),"") | G22: =IFERROR(algoritmo!F22,"") | H22: =IF(J22="◄◄","↑","") | I22: =IFERROR(algoritmo!J22,"") | J22: =IF(G22="","",IF(algoritmo!$L$4=1,IF(algoritmo!F22>=algoritmo!G21,"◄◄",""),IF(algoritmo!I21+algoritmo!B22=$O$14,"Ciclo com Lucro",IF(algoritmo!H22=$O$13-$O$14+1,"Ciclo com Perda"," "&($O$13-$O$14-algoritmo!H22)&"")))) | K22: =IF(#REF!="Progressivo",algoritmo!E22,"") -> #REF! | L22: =IF(#REF!="Progressivo",IF(K22="","",K22),"") -> #REF!
C23: =IF(C22<$O$13,C22+1,IF(D22=""," ",C22+1)) | E23: =IFERROR(algoritmo!C23,"") | F23: =IFERROR(IF(algoritmo!D23=0,-E23,algoritmo!D23),"") | G23: =IFERROR(algoritmo!F23,"") | H23: =IF(J23="◄◄","↑","") | I23: =IFERROR(algoritmo!J23,"") | J23: =IF(G23="","",IF(algoritmo!$L$4=1,IF(algoritmo!F23>=algoritmo!G22,"◄◄",""),IF(algoritmo!I22+algoritmo!B23=$O$14,"Ciclo com Lucro",IF(algoritmo!H23=$O$13-$O$14+1,"Ciclo com Perda"," "&($O$13-$O$14-algoritmo!H23)&"")))) | K23: =IF(#REF!="Progressivo",algoritmo!E23,"") -> #REF! | L23: =IF(#REF!="Progressivo",IF(K23="","",K23),"") -> #REF! | N23: Situação Atual
C24: =IF(C23<$O$13,C23+1,IF(D23=""," ",C23+1)) | E24: =IFERROR(algoritmo!C24,"") | F24: =IFERROR(IF(algoritmo!D24=0,-E24,algoritmo!D24),"") | G24: =IFERROR(algoritmo!F24,"") | H24: =IF(J24="◄◄","↑","") | I24: =IFERROR(algoritmo!J24,"") | J24: =IF(G24="","",IF(algoritmo!$L$4=1,IF(algoritmo!F24>=algoritmo!G23,"◄◄",""),IF(algoritmo!I23+algoritmo!B24=$O$14,"Ciclo com Lucro",IF(algoritmo!H24=$O$13-$O$14+1,"Ciclo com Perda"," "&($O$13-$O$14-algoritmo!H24)&"")))) | K24: =IF(#REF!="Progressivo",algoritmo!E24,"") -> #REF! | L24: =IF(#REF!="Progressivo",IF(K24="","",K24),"") -> #REF! | N24: Capital Atual Disponível | O24: =IFERROR(LOOKUP(2,1/(LEN(G3:G103)>0),G3:G103),"") -> 206.66667
C25: =IF(C24<$O$13,C24+1,IF(D24=""," ",C24+1)) | E25: =IFERROR(algoritmo!C25,"") | F25: =IFERROR(IF(algoritmo!D25=0,-E25,algoritmo!D25),"") | G25: =IFERROR(algoritmo!F25,"") | H25: =IF(J25="◄◄","↑","") | I25: =IFERROR(algoritmo!J25,"") | J25: =IF(G25="","",IF(algoritmo!$L$4=1,IF(algoritmo!F25>=algoritmo!G24,"◄◄",""),IF(algoritmo!I24+algoritmo!B25=$O$14,"Ciclo com Lucro",IF(algoritmo!H25=$O$13-$O$14+1,"Ciclo com Perda"," "&($O$13-$O$14-algoritmo!H25)&"")))) | K25: =IF(#REF!="Progressivo",algoritmo!E25,"") -> #REF! | L25: =IF(#REF!="Progressivo",IF(K25="","",K25),"") -> #REF! | N25: Balanço | O25: =IFERROR(O24-O12,"") -> 6.6666667 | P25: =IFERROR(O25/O12,"") -> 0.033333333
C26: =IF(C25<$O$13,C25+1,IF(D25=""," ",C25+1)) | E26: =IFERROR(algoritmo!C26,"") | F26: =IFERROR(IF(algoritmo!D26=0,-E26,algoritmo!D26),"") | G26: =IFERROR(algoritmo!F26,"") | H26: =IF(J26="◄◄","↑","") | I26: =IFERROR(algoritmo!J26,"") | J26: =IF(G26="","",IF(algoritmo!$L$4=1,IF(algoritmo!F26>=algoritmo!G25,"◄◄",""),IF(algoritmo!I25+algoritmo!B26=$O$14,"Ciclo com Lucro",IF(algoritmo!H26=$O$13-$O$14+1,"Ciclo com Perda"," "&($O$13-$O$14-algoritmo!H26)&"")))) | K26: =IF(#REF!="Progressivo",algoritmo!E26,"") -> #REF! | L26: =IF(#REF!="Progressivo",IF(K26="","",K26),"") -> #REF!
C27: =IF(C26<$O$13,C26+1,IF(D26=""," ",C26+1)) | E27: =IFERROR(algoritmo!C27,"") | F27: =IFERROR(IF(algoritmo!D27=0,-E27,algoritmo!D27),"") | G27: =IFERROR(algoritmo!F27,"") | H27: =IF(J27="◄◄","↑","") | I27: =IFERROR(algoritmo!J27,"") | J27: =IF(G27="","",IF(algoritmo!$L$4=1,IF(algoritmo!F27>=algoritmo!G26,"◄◄",""),IF(algoritmo!I26+algoritmo!B27=$O$14,"Ciclo com Lucro",IF(algoritmo!H27=$O$13-$O$14+1,"Ciclo com Perda"," "&($O$13-$O$14-algoritmo!H27)&"")))) | K27: =IF(#REF!="Progressivo",algoritmo!E27,"") -> #REF! | L27: =IF(#REF!="Progressivo",IF(K27="","",K27),"") -> #REF! | N27: Vitórias | O27: =COUNTIF(algoritmo!B2:B102,"=1") -> 1 | P27: =IF(O28+O27=0,"-",O27/(O28+O27)) -> 0.5
C28: =IF(C27<$O$13,C27+1,IF(D27=""," ",C27+1)) | E28: =IFERROR(algoritmo!C28,"") | F28: =IFERROR(IF(algoritmo!D28=0,-E28,algoritmo!D28),"") | G28: =IFERROR(algoritmo!F28,"") | H28: =IF(J28="◄◄","↑","") | I28: =IFERROR(algoritmo!J28,"") | J28: =IF(G28="","",IF(algoritmo!$L$4=1,IF(algoritmo!F28>=algoritmo!G27,"◄◄",""),IF(algoritmo!I27+algoritmo!B28=$O$14,"Ciclo com Lucro",IF(algoritmo!H28=$O$13-$O$14+1,"Ciclo com Perda"," "&($O$13-$O$14-algoritmo!H28)&"")))) | K28: =IF(#REF!="Progressivo",algoritmo!E28,"") -> #REF! | L28: =IF(#REF!="Progressivo",IF(K28="","",K28),"") -> #REF! | N28: Derrotas | O28: =COUNTIF(algoritmo!B2:B102,"=0") -> 1
C29: =IF(C28<$O$13,C28+1,IF(D28=""," ",C28+1)) | E29: =IFERROR(algoritmo!C29,"") | F29: =IFERROR(IF(algoritmo!D29=0,-E29,algoritmo!D29),"") | G29: =IFERROR(algoritmo!F29,"") | H29: =IF(J29="◄◄","↑","") | I29: =IFERROR(algoritmo!J29,"") | J29: =IF(G29="","",IF(algoritmo!$L$4=1,IF(algoritmo!F29>=algoritmo!G28,"◄◄",""),IF(algoritmo!I28+algoritmo!B29=$O$14,"Ciclo com Lucro",IF(algoritmo!H29=$O$13-$O$14+1,"Ciclo com Perda"," "&($O$13-$O$14-algoritmo!H29)&"")))) | K29: =IF(#REF!="Progressivo",algoritmo!E29,"") -> #REF! | L29: =IF(#REF!="Progressivo",IF(K29="","",K29),"") -> #REF!
C30: =IF(C29<$O$13,C29+1,IF(D29=""," ",C29+1)) | E30: =IFERROR(algoritmo!C30,"") | F30: =IFERROR(IF(algoritmo!D30=0,-E30,algoritmo!D30),"") | G30: =IFERROR(algoritmo!F30,"") | H30: =IF(J30="◄◄","↑","") | I30: =IFERROR(algoritmo!J30,"") | J30: =IF(G30="","",IF(algoritmo!$L$4=1,IF(algoritmo!F30>=algoritmo!G29,"◄◄",""),IF(algoritmo!I29+algoritmo!B30=$O$14,"Ciclo com Lucro",IF(algoritmo!H30=$O$13-$O$14+1,"Ciclo com Perda"," "&($O$13-$O$14-algoritmo!H30)&"")))) | K30: =IF(#REF!="Progressivo",algoritmo!E30,"") -> #REF! | L30: =IF(#REF!="Progressivo",IF(K30="","",K30),"") -> #REF!
C31: =IF(C30<$O$13,C30+1,IF(D30=""," ",C30+1)) | E31: =IFERROR(algoritmo!C31,"") | F31: =IFERROR(IF(algoritmo!D31=0,-E31,algoritmo!D31),"") | G31: =IFERROR(algoritmo!F31,"") | H31: =IF(J31="◄◄","↑","") | I31: =IFERROR(algoritmo!J31,"") | J31: =IF(G31="","",IF(algoritmo!$L$4=1,IF(algoritmo!F31>=algoritmo!G30,"◄◄",""),IF(algoritmo!I30+algoritmo!B31=$O$14,"Ciclo com Lucro",IF(algoritmo!H31=$O$13-$O$14+1,"Ciclo com Perda"," "&($O$13-$O$14-algoritmo!H31)&"")))) | K31: =IF(#REF!="Progressivo",algoritmo!E31,"") -> #REF! | L31: =IF(#REF!="Progressivo",IF(K31="","",K31),"") -> #REF!
C32: =IF(C31<$O$13,C31+1,IF(D31=""," ",C31+1)) | E32: =IFERROR(algoritmo!C32,"") | F32: =IFERROR(IF(algoritmo!D32=0,-E32,algoritmo!D32),"") | G32: =IFERROR(algoritmo!F32,"") | H32: =IF(J32="◄◄","↑","") | I32: =IFERROR(algoritmo!J32,"") | J32: =IF(G32="","",IF(algoritmo!$L$4=1,IF(algoritmo!F32>=algoritmo!G31,"◄◄",""),IF(algoritmo!I31+algoritmo!B32=$O$14,"Ciclo com Lucro",IF(algoritmo!H32=$O$13-$O$14+1,"Ciclo com Perda"," "&($O$13-$O$14-algoritmo!H32)&"")))) | K32: =IF(#REF!="Progressivo",algoritmo!E32,"") -> #REF! | L32: =IF(#REF!="Progressivo",IF(K32="","",K32),"") -> #REF!
C33: =IF(C32<$O$13,C32+1,IF(D32=""," ",C32+1)) | E33: =IFERROR(algoritmo!C33,"") | F33: =IFERROR(IF(algoritmo!D33=0,-E33,algoritmo!D33),"") | G33: =IFERROR(algoritmo!F33,"") | H33: =IF(J33="◄◄","↑","") | I33: =IFERROR(algoritmo!J33,"") | J33: =IF(G33="","",IF(algoritmo!$L$4=1,IF(algoritmo!F33>=algoritmo!G32,"◄◄",""),IF(algoritmo!I32+algoritmo!B33=$O$14,"Ciclo com Lucro",IF(algoritmo!H33=$O$13-$O$14+1,"Ciclo com Perda"," "&($O$13-$O$14-algoritmo!H33)&"")))) | K33: =IF(#REF!="Progressivo",algoritmo!E33,"") -> #REF! | L33: =IF(#REF!="Progressivo",IF(K33="","",K33),"") -> #REF!
C34: =IF(C33<$O$13,C33+1,IF(D33=""," ",C33+1)) | E34: =IFERROR(algoritmo!C34,"") | F34: =IFERROR(IF(algoritmo!D34=0,-E34,algoritmo!D34),"") | G34: =IFERROR(algoritmo!F34,"") | H34: =IF(J34="◄◄","↑","") | I34: =IFERROR(algoritmo!J34,"") | J34: =IF(G34="","",IF(algoritmo!$L$4=1,IF(algoritmo!F34>=algoritmo!G33,"◄◄",""),IF(algoritmo!I33+algoritmo!B34=$O$14,"Ciclo com Lucro",IF(algoritmo!H34=$O$13-$O$14+1,"Ciclo com Perda"," "&($O$13-$O$14-algoritmo!H34)&"")))) | K34: =IF(#REF!="Progressivo",algoritmo!E34,"") -> #REF! | L34: =IF(#REF!="Progressivo",IF(K34="","",K34),"") -> #REF!
C35: =IF(C34<$O$13,C34+1,IF(D34=""," ",C34+1)) | E35: =IFERROR(algoritmo!C35,"") | F35: =IFERROR(IF(algoritmo!D35=0,-E35,algoritmo!D35),"") | G35: =IFERROR(algoritmo!F35,"") | H35: =IF(J35="◄◄","↑","") | I35: =IFERROR(algoritmo!J35,"") | J35: =IF(G35="","",IF(algoritmo!$L$4=1,IF(algoritmo!F35>=algoritmo!G34,"◄◄",""),IF(algoritmo!I34+algoritmo!B35=$O$14,"Ciclo com Lucro",IF(algoritmo!H35=$O$13-$O$14+1,"Ciclo com Perda"," "&($O$13-$O$14-algoritmo!H35)&"")))) | K35: =IF(#REF!="Progressivo",algoritmo!E35,"") -> #REF! | L35: =IF(#REF!="Progressivo",IF(K35="","",K35),"") -> #REF!
C36: =IF(C35<$O$13,C35+1,IF(D35=""," ",C35+1)) | E36: =IFERROR(algoritmo!C36,"") | F36: =IFERROR(IF(algoritmo!D36=0,-E36,algoritmo!D36),"") | G36: =IFERROR(algoritmo!F36,"") | H36: =IF(J36="◄◄","↑","") | I36: =IFERROR(algoritmo!J36,"") | J36: =IF(G36="","",IF(algoritmo!$L$4=1,IF(algoritmo!F36>=algoritmo!G35,"◄◄",""),IF(algoritmo!I35+algoritmo!B36=$O$14,"Ciclo com Lucro",IF(algoritmo!H36=$O$13-$O$14+1,"Ciclo com Perda"," "&($O$13-$O$14-algoritmo!H36)&"")))) | K36: =IF(#REF!="Progressivo",algoritmo!E36,"") -> #REF! | L36: =IF(#REF!="Progressivo",IF(K36="","",K36),"") -> #REF!
C37: =IF(C36<$O$13,C36+1,IF(D36=""," ",C36+1)) | E37: =IFERROR(algoritmo!C37,"") | F37: =IFERROR(IF(algoritmo!D37=0,-E37,algoritmo!D37),"") | G37: =IFERROR(algoritmo!F37,"") | H37: =IF(J37="◄◄","↑","") | I37: =IFERROR(algoritmo!J37,"") | J37: =IF(G37="","",IF(algoritmo!$L$4=1,IF(algoritmo!F37>=algoritmo!G36,"◄◄",""),IF(algoritmo!I36+algoritmo!B37=$O$14,"Ciclo com Lucro",IF(algoritmo!H37=$O$13-$O$14+1,"Ciclo com Perda"," "&($O$13-$O$14-algoritmo!H37)&"")))) | K37: =IF(#REF!="Progressivo",algoritmo!E37,"") -> #REF! | L37: =IF(#REF!="Progressivo",IF(K37="","",K37),"") -> #REF!
C38: =IF(C37<$O$13,C37+1,IF(D37=""," ",C37+1)) | E38: =IFERROR(algoritmo!C38,"") | F38: =IFERROR(IF(algoritmo!D38=0,-E38,algoritmo!D38),"") | G38: =IFERROR(algoritmo!F38,"") | H38: =IF(J38="◄◄","↑","") | I38: =IFERROR(algoritmo!J38,"") | J38: =IF(G38="","",IF(algoritmo!$L$4=1,IF(algoritmo!F38>=algoritmo!G37,"◄◄",""),IF(algoritmo!I37+algoritmo!B38=$O$14,"Ciclo com Lucro",IF(algoritmo!H38=$O$13-$O$14+1,"Ciclo com Perda"," "&($O$13-$O$14-algoritmo!H38)&"")))) | K38: =IF(#REF!="Progressivo",algoritmo!E38,"") -> #REF! | L38: =IF(#REF!="Progressivo",IF(K38="","",K38),"") -> #REF!
C39: =IF(C38<$O$13,C38+1,IF(D38=""," ",C38+1)) | E39: =IFERROR(algoritmo!C39,"") | F39: =IFERROR(IF(algoritmo!D39=0,-E39,algoritmo!D39),"") | G39: =IFERROR(algoritmo!F39,"") | H39: =IF(J39="◄◄","↑","") | I39: =IFERROR(algoritmo!J39,"") | J39: =IF(G39="","",IF(algoritmo!$L$4=1,IF(algoritmo!F39>=algoritmo!G38,"◄◄",""),IF(algoritmo!I38+algoritmo!B39=$O$14,"Ciclo com Lucro",IF(algoritmo!H39=$O$13-$O$14+1,"Ciclo com Perda"," "&($O$13-$O$14-algoritmo!H39)&"")))) | K39: =IF(#REF!="Progressivo",algoritmo!E39,"") -> #REF! | L39: =IF(#REF!="Progressivo",IF(K39="","",K39),"") -> #REF!
C40: =IF(C39<$O$13,C39+1,IF(D39=""," ",C39+1)) | E40: =IFERROR(algoritmo!C40,"") | F40: =IFERROR(IF(algoritmo!D40=0,-E40,algoritmo!D40),"") | G40: =IFERROR(algoritmo!F40,"") | H40: =IF(J40="◄◄","↑","") | I40: =IFERROR(algoritmo!J40,"") | J40: =IF(G40="","",IF(algoritmo!$L$4=1,IF(algoritmo!F40>=algoritmo!G39,"◄◄",""),IF(algoritmo!I39+algoritmo!B40=$O$14,"Ciclo com Lucro",IF(algoritmo!H40=$O$13-$O$14+1,"Ciclo com Perda"," "&($O$13-$O$14-algoritmo!H40)&"")))) | K40: =IF(#REF!="Progressivo",algoritmo!E40,"") -> #REF! | L40: =IF(#REF!="Progressivo",IF(K40="","",K40),"") -> #REF!
... C102: =IF(C101<$O$13,C101+1,IF(D101=""," ",C101+1)) | E102: =IFERROR(algoritmo!C102,"") | F102: =IFERROR(IF(algoritmo!D102=0,-E102,algoritmo!D102),"") | G102: =IFERROR(algoritmo!F102,"") | H102: =IF(J102="◄◄","↑","") | I102: =IFERROR(algoritmo!J102,"") | J102: =IF(G102="","",IF(algoritmo!$L$4=1,IF(algoritmo!F102>=algoritmo!G101,"◄◄",""),IF(algoritmo!I101+algoritmo!B102=$O$14,"Ciclo com Lucro",IF(algoritmo!H102=$O$13-$O$14+1,"Ciclo com Perda"," "&($O$13-$O$14-algoritmo!H102)&"")))) | K102: =IF(#REF!="Progressivo",algoritmo!E102,"") -> #REF! | L102: =IF(#REF!="Progressivo",IF(K102="","",K102),"") -> #REF!

Sheet algoritmo
F1: Banca (Cassa) | G1: Max | H1: Loss (Perdite) | I1: Win (Vincite) | K1: Operações (eventi) | L1: =Gerenciamento!$O$13 -> 7 | N1: 0 | O1: =IF(N1<$L$2,N1+1) -> 1 | P1: =IF(O1<$L$2,O1+1) -> 2 | Q1: =IF(P1<$L$2,P1+1) -> FALSE | R1: =IF(Q1<$L$2,Q1+1) -> FALSE | S1: =IF(R1<$L$2,R1+1) -> FALSE | T1: =IF(S1<$L$2,S1+1) -> FALSE | U1: =IF(T1<$L$2,T1+1) -> FALSE | V1: =IF(U1<$L$2,U1+1) -> FALSE | ... DJ1: =IF(DI1<$L$2,DI1+1) -> FALSE
A2: W-L | B2: W-L | C2: Investimento | D2: Retorno (Ritorno) | E2: Cancelamento (Prelievo) | F2: =Gerenciamento!$O$12 -> 200 | G2: =Gerenciamento!$O$12 -> 200 | H2: 0 | I2: 0 | K2: Oper. Win (atesi) | L2: =Gerenciamento!$O$14 -> 2 | M2: 0 | N2: =IF(N$1>$L$2,"",IF(N$1=$L$2,1,IF($L$2-N$1=$L$1-$M2,$L$3^($L$1-$M2),($L$3*N3*O3/(N3+($L$3-1)*O3))))) -> 1.0666667 | O2: =IF(O$1>$L$2,"",IF(O$1=$L$2,1,IF($L$2-O$1=$L$1-$M2,$L$3^($L$1-$M2),($L$3*O3*P3/(O3+($L$3-1)*P3))))) -> 1.007874 | P2: =IF(P$1>$L$2,"",IF(P$1=$L$2,1,IF($L$2-P$1=$L$1-$M2,$L$3^($L$1-$M2),($L$3*P3*Q3/(P3+($L$3-1)*Q3))))) -> 1 | Q2: =IF(Q$1>$L$2,"",IF(Q$1=$L$2,1,IF($L$2-Q$1=$L$1-$M2,$L$3^($L$1-$M2),($L$3*Q3*R3/(Q3+($L$3-1)*R3))))) | R2: =IF(R$1>$L$2,"",IF(R$1=$L$2,1,IF($L$2-R$1=$L$1-$M2,$L$3^($L$1-$M2),($L$3*R3*S3/(R3+($L$3-1)*S3))))) | S2: =IF(S$1>$L$2,"",IF(S$1=$L$2,1,IF($L$2-S$1=$L$1-$M2,$L$3^($L$1-$M2),($L$3*S3*T3/(S3+($L$3-1)*T3))))) | T2: =IF(T$1>$L$2,"",IF(T$1=$L$2,1,IF($L$2-T$1=$L$1-$M2,$L$3^($L$1-$M2),($L$3*T3*U3/(T3+($L$3-1)*U3))))) | U2: =IF(U$1>$L$2,"",IF(U$1=$L$2,1,IF($L$2-U$1=$L$1-$M2,$L$3^($L$1-$M2),($L$3*U3*V3/(U3+($L$3-1)*V3))))) | ... DJ2: =IF(DJ$1>$L$2,"",IF(DJ$1=$L$2,1,IF($L$2-DJ$1=$L$1-$M2,$L$3^($L$1-$M2),($L$3*DJ3*DK3/(DJ3+($L$3-1)*DK3)))))
A3: =Gerenciamento!D3 -> W | B3: =IF(OR(I2=$L$2,H2=1+$L$1-$L$2),"",IF(A3="l",0,IF(A3="w",1,""))) -> 1 | C3: =IF(OR(I2>=$L$2,D2=""),"",IF(ISERROR((1-$L$3*INDEX($N$2:$DJ$101,H2+I2+2,I2+2)/(INDEX($N$2:$DJ$101,H2+I2+2,I2+1)+($L$3-1)*(INDEX($N$2:$DJ$101,H2+I2+2,I2+2))))*$F2),$F2,(1-$L$3*INDEX($N$2:$DJ$101,H2+I2+2,I2+2)/(INDEX($N$2:$DJ$101,H2+I2+2,I2+1)+($L$3-1)*(INDEX($N$2:$DJ$101,H2+I2+2,I2+2))))*$F2)) -> 10 | D3: =IF(I2>=$L$2,"",IF(B3="","",C3*($L$3-1)*B3)) -> 10 | E3: =IF(B3="","",(D3-(IF((D3+F2)<=G2,D3,(G2-F2))))*(100-$L$5)/100) -> 0 | F3: =IF(I2>=$L$2,"",IF(B3="","",IF(B3=0,F2-C3,IF(((F2+D3)-G2)>=0,F2+(G2-F2)+((D3-(G2-F2))*$L$5/100),F2+D3)))) -> 210 | G3: =IF(F3>G2,F3,G2) -> 210 | H3: =IF($L$4=0,IF(I2+B3=$L$2,0,IF(B3=0,H2+1,H2)),IF(F3>=G2,0,IF(B3=0,H2+1,H2))) -> 0 | I3: =IF($L$4=0,IF(I2+B3=$L$2,0,IF(B3=1,I2+1,I2)),IF(F3>=G2,0,IF(B3=1,I2+1,I2))) -> 1 | J3: =IF(B3="","",IF(ISERROR((B3+I2)/(H2+I2+1)),0,(B3+I2)/(H2+I2+1))) -> 1 | K3: Payout (quota) | L3: =Gerenciamento!$O$15 -> 2 | M3: =IF(M2<($L$1-1),M2+1) -> 1 | N3: =IF(N$1>$L$2,"",IF(N$1=$L$2,1,IF($L$2-N$1=$L$1-$M3,$L$3^($L$1-$M3),($L$3*N4*O4/(N4+($L$3-1)*O4))))) -> 1.122807 | O3: =IF(O$1>$L$2,"",IF(O$1=$L$2,1,IF($L$2-O$1=$L$1-$M3,$L$3^($L$1-$M3),($L$3*O4*P4/(O4+($L$3-1)*P4))))) -> 1.015873 | P3: =IF(P$1>$L$2,"",IF(P$1=$L$2,1,IF($L$2-P$1=$L$1-$M3,$L$3^($L$1-$M3),($L$3*P4*Q4/(P4+($L$3-1)*Q4))))) -> 1 | Q3: =IF(Q$1>$L$2,"",IF(Q$1=$L$2,1,IF($L$2-Q$1=$L$1-$M3,$L$3^($L$1-$M3),($L$3*Q4*R4/(Q4+($L$3-1)*R4))))) | R3: =IF(R$1>$L$2,"",IF(R$1=$L$2,1,IF($L$2-R$1=$L$1-$M3,$L$3^($L$1-$M3),($L$3*R4*S4/(R4+($L$3-1)*S4))))) | S3: =IF(S$1>$L$2,"",IF(S$1=$L$2,1,IF($L$2-S$1=$L$1-$M3,$L$3^($L$1-$M3),($L$3*S4*T4/(S4+($L$3-1)*T4))))) | T3: =IF(T$1>$L$2,"",IF(T$1=$L$2,1,IF($L$2-T$1=$L$1-$M3,$L$3^($L$1-$M3),($L$3*T4*U4/(T4+($L$3-1)*U4))))) | U3: =IF(U$1>$L$2,"",IF(U$1=$L$2,1,IF($L$2-U$1=$L$1-$M3,$L$3^($L$1-$M3),($L$3*U4*V4/(U4+($L$3-1)*V4))))) | ... DJ3: =IF(DJ$1>$L$2,"",IF(DJ$1=$L$2,1,IF($L$2-DJ$1=$L$1-$M3,$L$3^($L$1-$M3),($L$3*DJ4*DK4/(DJ4+($L$3-1)*DK4)))))
A4: =Gerenciamento!D4 -> L | B4: =IF(OR(I3=$L$2,H3=1+$L$1-$L$2),"",IF(A4="l",0,IF(A4="w",1,""))) -> 0 | C4: =IF(OR(I3>=$L$2,D3=""),"",IF(ISERROR((1-$L$3*INDEX($N$2:$DJ$101,H3+I3+2,I3+2)/(INDEX($N$2:$DJ$101,H3+I3+2,I3+1)+($L$3-1)*(INDEX($N$2:$DJ$101,H3+I3+2,I3+2))))*$F3),$F3,(1-$L$3*INDEX($N$2:$DJ$101,H3+I3+2,I3+2)/(INDEX($N$2:$DJ$101,H3+I3+2,I3+1)+($L$3-1)*(INDEX($N$2:$DJ$101,H3+I3+2,I3+2))))*$F3)) -> 3.3333333 | D4: =IF(I3>=$L$2,"",IF(B4="","",C4*($L$3-1)*B4)) -> 0 | E4: =IF(B4="","",(D4-(IF((D4+F3)<=G3,D4,(G3-F3))))*(100-$L$5)/100) -> 0 | F4: =IF(I3>=$L$2,"",IF(B4="","",IF(B4=0,F3-C4,IF(((F3+D4)-G3)>=0,F3+(G3-F3)+((D4-(G3-F3))*$L$5/100),F3+D4)))) -> 206.66667 | G4: =IF(F4>G3,F4,G3) -> 210 | H4: =IF($L$4=0,IF(I3+B4=$L$2,0,IF(B4=0,H3+1,H3)),IF(F4>=G3,0,IF(B4=0,H3+1,H3))) -> 1 | I4: =IF($L$4=0,IF(I3+B4=$L$2,0,IF(B4=1,I3+1,I3)),IF(F4>=G3,0,IF(B4=1,I3+1,I3))) -> 1 | J4: =IF(B4="","",IF(ISERROR((B4+I3)/(H3+I3+1)),0,(B4+I3)/(H3+I3+1))) -> 0.5 | K4: Masaniello tippo | L4: =IF(Gerenciamento!O16="Normal",0,1) -> 0 | M4: =IF(M3<($L$1-1),M3+1) -> 2 | N4: =IF(N$1>$L$2,"",IF(N$1=$L$2,1,IF($L$2-N$1=$L$1-$M4,$L$3^($L$1-$M4),($L$3*N5*O5/(N5+($L$3-1)*O5))))) -> 1.2307692 | O4: =IF(O$1>$L$2,"",IF(O$1=$L$2,1,IF($L$2-O$1=$L$1-$M4,$L$3^($L$1-$M4),($L$3*O5*P5/(O5+($L$3-1)*P5))))) -> 1.0322581 | P4: =IF(P$1>$L$2,"",IF(P$1=$L$2,1,IF($L$2-P$1=$L$1-$M4,$L$3^($L$1-$M4),($L$3*P5*Q5/(P5+($L$3-1)*Q5))))) -> 1 | Q4: =IF(Q$1>$L$2,"",IF(Q$1=$L$2,1,IF($L$2-Q$1=$L$1-$M4,$L$3^($L$1-$M4),($L$3*Q5*R5/(Q5+($L$3-1)*R5))))) | R4: =IF(R$1>$L$2,"",IF(R$1=$L$2,1,IF($L$2-R$1=$L$1-$M4,$L$3^($L$1-$M4),($L$3*R5*S5/(R5+($L$3-1)*S5))))) | S4: =IF(S$1>$L$2,"",IF(S$1=$L$2,1,IF($L$2-S$1=$L$1-$M4,$L$3^($L$1-$M4),($L$3*S5*T5/(S5+($L$3-1)*T5))))) | T4: =IF(T$1>$L$2,"",IF(T$1=$L$2,1,IF($L$2-T$1=$L$1-$M4,$L$3^($L$1-$M4),($L$3*T5*U5/(T5+($L$3-1)*U5))))) | U4: =IF(U$1>$L$2,"",IF(U$1=$L$2,1,IF($L$2-U$1=$L$1-$M4,$L$3^($L$1-$M4),($L$3*U5*V5/(U5+($L$3-1)*V5))))) | ... DJ4: =IF(DJ$1>$L$2,"",IF(DJ$1=$L$2,1,IF($L$2-DJ$1=$L$1-$M4,$L$3^($L$1-$M4),($L$3*DJ5*DK5/(DJ5+($L$3-1)*DK5)))))
A5: =Gerenciamento!D5 -> 0 | B5: =IF(OR(I4=$L$2,H4=1+$L$1-$L$2),"",IF(A5="l",0,IF(A5="w",1,""))) | C5: =IF(OR(I4>=$L$2,D4=""),"",IF(ISERROR((1-$L$3*INDEX($N$2:$DJ$101,H4+I4+2,I4+2)/(INDEX($N$2:$DJ$101,H4+I4+2,I4+1)+($L$3-1)*(INDEX($N$2:$DJ$101,H4+I4+2,I4+2))))*$F4),$F4,(1-$L$3*INDEX($N$2:$DJ$101,H4+I4+2,I4+2)/(INDEX($N$2:$DJ$101,H4+I4+2,I4+1)+($L$3-1)*(INDEX($N$2:$DJ$101,H4+I4+2,I4+2))))*$F4)) -> 6.6666667 | D5: =IF(I4>=$L$2,"",IF(B5="","",C5*($L$3-1)*B5)) | E5: =IF(B5="","",(D5-(IF((D5+F4)<=G4,D5,(G4-F4))))*(100-$L$5)/100) | F5: =IF(I4>=$L$2,"",IF(B5="","",IF(B5=0,F4-C5,IF(((F4+D5)-G4)>=0,F4+(G4-F4)+((D5-(G4-F4))*$L$5/100),F4+D5)))) | G5: =IF(F5>G4,F5,G4) | H5: =IF($L$4=0,IF(I4+B5=$L$2,0,IF(B5=0,H4+1,H4)),IF(F5>=G4,0,IF(B5=0,H4+1,H4))) -> #VALUE! | I5: =IF($L$4=0,IF(I4+B5=$L$2,0,IF(B5=1,I4+1,I4)),IF(F5>=G4,0,IF(B5=1,I4+1,I4))) -> #VALUE! | J5: =IF(B5="","",IF(ISERROR((B5+I4)/(H4+I4+1)),0,(B5+I4)/(H4+I4+1))) | K5: % da reinvestire | L5: 100 | M5: =IF(M4<($L$1-1),M4+1) -> 3 | N5: =IF(N$1>$L$2,"",IF(N$1=$L$2,1,IF($L$2-N$1=$L$1-$M5,$L$3^($L$1-$M5),($L$3*N6*O6/(N6+($L$3-1)*O6))))) -> 1.4545455 | O5: =IF(O$1>$L$2,"",IF(O$1=$L$2,1,IF($L$2-O$1=$L$1-$M5,$L$3^($L$1-$M5),($L$3*O6*P6/(O6+($L$3-1)*P6))))) -> 1.0666667 | P5: =IF(P$1>$L$2,"",IF(P$1=$L$2,1,IF($L$2-P$1=$L$1-$M5,$L$3^($L$1-$M5),($L$3*P6*Q6/(P6+($L$3-1)*Q6))))) -> 1 | Q5: =IF(Q$1>$L$2,"",IF(Q$1=$L$2,1,IF($L$2-Q$1=$L$1-$M5,$L$3^($L$1-$M5),($L$3*Q6*R6/(Q6+($L$3-1)*R6))))) | R5: =IF(R$1>$L$2,"",IF(R$1=$L$2,1,IF($L$2-R$1=$L$1-$M5,$L$3^($L$1-$M5),($L$3*R6*S6/(R6+($L$3-1)*S6))))) | S5: =IF(S$1>$L$2,"",IF(S$1=$L$2,1,IF($L$2-S$1=$L$1-$M5,$L$3^($L$1-$M5),($L$3*S6*T6/(S6+($L$3-1)*T6))))) | T5: =IF(T$1>$L$2,"",IF(T$1=$L$2,1,IF($L$2-T$1=$L$1-$M5,$L$3^($L$1-$M5),($L$3*T6*U6/(T6+($L$3-1)*U6))))) | U5: =IF(U$1>$L$2,"",IF(U$1=$L$2,1,IF($L$2-U$1=$L$1-$M5,$L$3^($L$1-$M5),($L$3*U6*V6/(U6+($L$3-1)*V6))))) | ... DJ5: =IF(DJ$1>$L$2,"",IF(DJ$1=$L$2,1,IF($L$2-DJ$1=$L$1-$M5,$L$3^($L$1-$M5),($L$3*DJ6*DK6/(DJ6+($L$3-1)*DK6)))))
A6: =Gerenciamento!D6 -> 0 | B6: =IF(OR(I5=$L$2,H5=1+$L$1-$L$2),"",IF(A6="l",0,IF(A6="w",1,""))) -> #VALUE! | C6: =IF(OR(I5>=$L$2,D5=""),"",IF(ISERROR((1-$L$3*INDEX($N$2:$DJ$101,H5+I5+2,I5+2)/(INDEX($N$2:$DJ$101,H5+I5+2,I5+1)+($L$3-1)*(INDEX($N$2:$DJ$101,H5+I5+2,I5+2))))*$F5),$F5,(1-$L$3*INDEX($N$2:$DJ$101,H5+I5+2,I5+2)/(INDEX($N$2:$DJ$101,H5+I5+2,I5+1)+($L$3-1)*(INDEX($N$2:$DJ$101,H5+I5+2,I5+2))))*$F5)) -> #VALUE! | D6: =IF(I5>=$L$2,"",IF(B6="","",C6*($L$3-1)*B6)) -> #VALUE! | E6: =IF(B6="","",(D6-(IF((D6+F5)<=G5,D6,(G5-F5))))*(100-$L$5)/100) -> #VALUE! | F6: =IF(I5>=$L$2,"",IF(B6="","",IF(B6=0,F5-C6,IF(((F5+D6)-G5)>=0,F5+(G5-F5)+((D6-(G5-F5))*$L$5/100),F5+D6)))) -> #VALUE! | G6: =IF(F6>G5,F6,G5) -> #VALUE! | H6: =IF($L$4=0,IF(I5+B6=$L$2,0,IF(B6=0,H5+1,H5)),IF(F6>=G5,0,IF(B6=0,H5+1,H5))) -> #VALUE! | I6: =IF($L$4=0,IF(I5+B6=$L$2,0,IF(B6=1,I5+1,I5)),IF(F6>=G5,0,IF(B6=1,I5+1,I5))) -> #VALUE! | J6: =IF(B6="","",IF(ISERROR((B6+I5)/(H5+I5+1)),0,(B6+I5)/(H5+I5+1))) -> #VALUE! | M6: =IF(M5<($L$1-1),M5+1) -> 4 | N6: =IF(N$1>$L$2,"",IF(N$1=$L$2,1,IF($L$2-N$1=$L$1-$M6,$L$3^($L$1-$M6),($L$3*N7*O7/(N7+($L$3-1)*O7))))) -> 2 | O6: =IF(O$1>$L$2,"",IF(O$1=$L$2,1,IF($L$2-O$1=$L$1-$M6,$L$3^($L$1-$M6),($L$3*O7*P7/(O7+($L$3-1)*P7))))) -> 1.1428571 | P6: =IF(P$1>$L$2,"",IF(P$1=$L$2,1,IF($L$2-P$1=$L$1-$M6,$L$3^($L$1-$M6),($L$3*P7*Q7/(P7+($L$3-1)*Q7))))) -> 1 | Q6: =IF(Q$1>$L$2,"",IF(Q$1=$L$2,1,IF($L$2-Q$1=$L$1-$M6,$L$3^($L$1-$M6),($L$3*Q7*R7/(Q7+($L$3-1)*R7))))) | R6: =IF(R$1>$L$2,"",IF(R$1=$L$2,1,IF($L$2-R$1=$L$1-$M6,$L$3^($L$1-$M6),($L$3*R7*S7/(R7+($L$3-1)*S7))))) | S6: =IF(S$1>$L$2,"",IF(S$1=$L$2,1,IF($L$2-S$1=$L$1-$M6,$L$3^($L$1-$M6),($L$3*S7*T7/(S7+($L$3-1)*T7))))) | T6: =IF(T$1>$L$2,"",IF(T$1=$L$2,1,IF($L$2-T$1=$L$1-$M6,$L$3^($L$1-$M6),($L$3*T7*U7/(T7+($L$3-1)*U7))))) | U6: =IF(U$1>$L$2,"",IF(U$1=$L$2,1,IF($L$2-U$1=$L$1-$M6,$L$3^($L$1-$M6),($L$3*U7*V7/(U7+($L$3-1)*V7))))) | ... DJ6: =IF(DJ$1>$L$2,"",IF(DJ$1=$L$2,1,IF($L$2-DJ$1=$L$1-$M6,$L$3^($L$1-$M6),($L$3*DJ7*DK7/(DJ7+($L$3-1)*DK7)))))
A7: =Gerenciamento!D7 -> 0 | B7: =IF(OR(I6=$L$2,H6=1+$L$1-$L$2),"",IF(A7="l",0,IF(A7="w",1,""))) -> #VALUE! | C7: =IF(OR(I6>=$L$2,D6=""),"",IF(ISERROR((1-$L$3*INDEX($N$2:$DJ$101,H6+I6+2,I6+2)/(INDEX($N$2:$DJ$101,H6+I6+2,I6+1)+($L$3-1)*(INDEX($N$2:$DJ$101,H6+I6+2,I6+2))))*$F6),$F6,(1-$L$3*INDEX($N$2:$DJ$101,H6+I6+2,I6+2)/(INDEX($N$2:$DJ$101,H6+I6+2,I6+1)+($L$3-1)*(INDEX($N$2:$DJ$101,H6+I6+2,I6+2))))*$F6)) -> #VALUE! | D7: =IF(I6>=$L$2,"",IF(B7="","",C7*($L$3-1)*B7)) -> #VALUE! | E7: =IF(B7="","",(D7-(IF((D7+F6)<=G6,D7,(G6-F6))))*(100-$L$5)/100) -> #VALUE! | F7: =IF(I6>=$L$2,"",IF(B7="","",IF(B7=0,F6-C7,IF(((F6+D7)-G6)>=0,F6+(G6-F6)+((D7-(G6-F6))*$L$5/100),F6+D7)))) -> #VALUE! | G7: =IF(F7>G6,F7,G6) -> #VALUE! | H7: =IF($L$4=0,IF(I6+B7=$L$2,0,IF(B7=0,H6+1,H6)),IF(F7>=G6,0,IF(B7=0,H6+1,H6))) -> #VALUE! | I7: =IF($L$4=0,IF(I6+B7=$L$2,0,IF(B7=1,I6+1,I6)),IF(F7>=G6,0,IF(B7=1,I6+1,I6))) -> #VALUE! | J7: =IF(B7="","",IF(ISERROR((B7+I6)/(H6+I6+1)),0,(B7+I6)/(H6+I6+1))) -> #VALUE! | M7: =IF(M6<($L$1-1),M6+1) -> 5 | N7: =IF(N$1>$L$2,"",IF(N$1=$L$2,1,IF($L$2-N$1=$L$1-$M7,$L$3^($L$1-$M7),($L$3*N8*O8/(N8+($L$3-1)*O8))))) -> 4 | O7: =IF(O$1>$L$2,"",IF(O$1=$L$2,1,IF($L$2-O$1=$L$1-$M7,$L$3^($L$1-$M7),($L$3*O8*P8/(O8+($L$3-1)*P8))))) -> 1.3333333 | P7: =IF(P$1>$L$2,"",IF(P$1=$L$2,1,IF($L$2-P$1=$L$1-$M7,$L$3^($L$1-$M7),($L$3*P8*Q8/(P8+($L$3-1)*Q8))))) -> 1 | Q7: =IF(Q$1>$L$2,"",IF(Q$1=$L$2,1,IF($L$2-Q$1=$L$1-$M7,$L$3^($L$1-$M7),($L$3*Q8*R8/(Q8+($L$3-1)*R8))))) | R7: =IF(R$1>$L$2,"",IF(R$1=$L$2,1,IF($L$2-R$1=$L$1-$M7,$L$3^($L$1-$M7),($L$3*R8*S8/(R8+($L$3-1)*S8))))) | S7: =IF(S$1>$L$2,"",IF(S$1=$L$2,1,IF($L$2-S$1=$L$1-$M7,$L$3^($L$1-$M7),($L$3*S8*T8/(S8+($L$3-1)*T8))))) | T7: =IF(T$1>$L$2,"",IF(T$1=$L$2,1,IF($L$2-T$1=$L$1-$M7,$L$3^($L$1-$M7),($L$3*T8*U8/(T8+($L$3-1)*U8))))) | U7: =IF(U$1>$L$2,"",IF(U$1=$L$2,1,IF($L$2-U$1=$L$1-$M7,$L$3^($L$1-$M7),($L$3*U8*V8/(U8+($L$3-1)*V8))))) | ... DJ7: =IF(DJ$1>$L$2,"",IF(DJ$1=$L$2,1,IF($L$2-DJ$1=$L$1-$M7,$L$3^($L$1-$M7),($L$3*DJ8*DK8/(DJ8+($L$3-1)*DK8)))))
A8: =Gerenciamento!D8 -> 0 | B8: =IF(OR(I7=$L$2,H7=1+$L$1-$L$2),"",IF(A8="l",0,IF(A8="w",1,""))) -> #VALUE! | C8: =IF(OR(I7>=$L$2,D7=""),"",IF(ISERROR((1-$L$3*INDEX($N$2:$DJ$101,H7+I7+2,I7+2)/(INDEX($N$2:$DJ$101,H7+I7+2,I7+1)+($L$3-1)*(INDEX($N$2:$DJ$101,H7+I7+2,I7+2))))*$F7),$F7,(1-$L$3*INDEX($N$2:$DJ$101,H7+I7+2,I7+2)/(INDEX($N$2:$DJ$101,H7+I7+2,I7+1)+($L$3-1)*(INDEX($N$2:$DJ$101,H7+I7+2,I7+2))))*$F7)) -> #VALUE! | D8: =IF(I7>=$L$2,"",IF(B8="","",C8*($L$3-1)*B8)) -> #VALUE! | E8: =IF(B8="","",(D8-(IF((D8+F7)<=G7,D8,(G7-F7))))*(100-$L$5)/100) -> #VALUE! | F8: =IF(I7>=$L$2,"",IF(B8="","",IF(B8=0,F7-C8,IF(((F7+D8)-G7)>=0,F7+(G7-F7)+((D8-(G7-F7))*$L$5/100),F7+D8)))) -> #VALUE! | G8: =IF(F8>G7,F8,G7) -> #VALUE! | H8: =IF($L$4=0,IF(I7+B8=$L$2,0,IF(B8=0,H7+1,H7)),IF(F8>=G7,0,IF(B8=0,H7+1,H7))) -> #VALUE! | I8: =IF($L$4=0,IF(I7+B8=$L$2,0,IF(B8=1,I7+1,I7)),IF(F8>=G7,0,IF(B8=1,I7+1,I7))) -> #VALUE! | J8: =IF(B8="","",IF(ISERROR((B8+I7)/(H7+I7+1)),0,(B8+I7)/(H7+I7+1))) -> #VALUE! | M8: =IF(M7<($L$1-1),M7+1) -> 6 | N8: =IF(N$1>$L$2,"",IF(N$1=$L$2,1,IF($L$2-N$1=$L$1-$M8,$L$3^($L$1-$M8),($L$3*N9*O9/(N9+($L$3-1)*O9))))) -> #DIV/0! | O8: =IF(O$1>$L$2,"",IF(O$1=$L$2,1,IF($L$2-O$1=$L$1-$M8,$L$3^($L$1-$M8),($L$3*O9*P9/(O9+($L$3-1)*P9))))) -> 2 | P8: =IF(P$1>$L$2,"",IF(P$1=$L$2,1,IF($L$2-P$1=$L$1-$M8,$L$3^($L$1-$M8),($L$3*P9*Q9/(P9+($L$3-1)*Q9))))) -> 1 | Q8: =IF(Q$1>$L$2,"",IF(Q$1=$L$2,1,IF($L$2-Q$1=$L$1-$M8,$L$3^($L$1-$M8),($L$3*Q9*R9/(Q9+($L$3-1)*R9))))) | R8: =IF(R$1>$L$2,"",IF(R$1=$L$2,1,IF($L$2-R$1=$L$1-$M8,$L$3^($L$1-$M8),($L$3*R9*S9/(R9+($L$3-1)*S9))))) | S8: =IF(S$1>$L$2,"",IF(S$1=$L$2,1,IF($L$2-S$1=$L$1-$M8,$L$3^($L$1-$M8),($L$3*S9*T9/(S9+($L$3-1)*T9))))) | T8: =IF(T$1>$L$2,"",IF(T$1=$L$2,1,IF($L$2-T$1=$L$1-$M8,$L$3^($L$1-$M8),($L$3*T9*U9/(T9+($L$3-1)*U9))))) | U8: =IF(U$1>$L$2,"",IF(U$1=$L$2,1,IF($L$2-U$1=$L$1-$M8,$L$3^($L$1-$M8),($L$3*U9*V9/(U9+($L$3-1)*V9))))) | ... DJ8: =IF(DJ$1>$L$2,"",IF(DJ$1=$L$2,1,IF($L$2-DJ$1=$L$1-$M8,$L$3^($L$1-$M8),($L$3*DJ9*DK9/(DJ9+($L$3-1)*DK9)))))
A9: =Gerenciamento!D9 -> 0 | B9: =IF(OR(I8=$L$2,H8=1+$L$1-$L$2),"",IF(A9="l",0,IF(A9="w",1,""))) -> #VALUE! | C9: =IF(OR(I8>=$L$2,D8=""),"",IF(ISERROR((1-$L$3*INDEX($N$2:$DJ$101,H8+I8+2,I8+2)/(INDEX($N$2:$DJ$101,H8+I8+2,I8+1)+($L$3-1)*(INDEX($N$2:$DJ$101,H8+I8+2,I8+2))))*$F8),$F8,(1-$L$3*INDEX($N$2:$DJ$101,H8+I8+2,I8+2)/(INDEX($N$2:$DJ$101,H8+I8+2,I8+1)+($L$3-1)*(INDEX($N$2:$DJ$101,H8+I8+2,I8+2))))*$F8)) -> #VALUE! | D9: =IF(I8>=$L$2,"",IF(B9="","",C9*($L$3-1)*B9)) -> #VALUE! | E9: =IF(B9="","",(D9-(IF((D9+F8)<=G8,D9,(G8-F8))))*(100-$L$5)/100) -> #VALUE! | F9: =IF(I8>=$L$2,"",IF(B9="","",IF(B9=0,F8-C9,IF(((F8+D9)-G8)>=0,F8+(G8-F8)+((D9-(G8-F8))*$L$5/100),F8+D9)))) -> #VALUE! | G9: =IF(F9>G8,F9,G8) -> #VALUE! | H9: =IF($L$4=0,IF(I8+B9=$L$2,0,IF(B9=0,H8+1,H8)),IF(F9>=G8,0,IF(B9=0,H8+1,H8))) -> #VALUE! | I9: =IF($L$4=0,IF(I8+B9=$L$2,0,IF(B9=1,I8+1,I8)),IF(F9>=G8,0,IF(B9=1,I8+1,I8))) -> #VALUE! | J9: =IF(B9="","",IF(ISERROR((B9+I8)/(H8+I8+1)),0,(B9+I8)/(H8+I8+1))) -> #VALUE! | M9: =IF(M8<($L$1-1),M8+1) -> FALSE | N9: =IF(N$1>$L$2,"",IF(N$1=$L$2,1,IF($L$2-N$1=$L$1-$M9,$L$3^($L$1-$M9),($L$3*N10*O10/(N10+($L$3-1)*O10))))) -> #DIV/0! | O9: =IF(O$1>$L$2,"",IF(O$1=$L$2,1,IF($L$2-O$1=$L$1-$M9,$L$3^($L$1-$M9),($L$3*O10*P10/(O10+($L$3-1)*P10))))) -> #DIV/0! | P9: =IF(P$1>$L$2,"",IF(P$1=$L$2,1,IF($L$2-P$1=$L$1-$M9,$L$3^($L$1-$M9),($L$3*P10*Q10/(P10+($L$3-1)*Q10))))) -> 1 | Q9: =IF(Q$1>$L$2,"",IF(Q$1=$L$2,1,IF($L$2-Q$1=$L$1-$M9,$L$3^($L$1-$M9),($L$3*Q10*R10/(Q10+($L$3-1)*R10))))) | R9: =IF(R$1>$L$2,"",IF(R$1=$L$2,1,IF($L$2-R$1=$L$1-$M9,$L$3^($L$1-$M9),($L$3*R10*S10/(R10+($L$3-1)*S10))))) | S9: =IF(S$1>$L$2,"",IF(S$1=$L$2,1,IF($L$2-S$1=$L$1-$M9,$L$3^($L$1-$M9),($L$3*S10*T10/(S10+($L$3-1)*T10))))) | T9: =IF(T$1>$L$2,"",IF(T$1=$L$2,1,IF($L$2-T$1=$L$1-$M9,$L$3^($L$1-$M9),($L$3*T10*U10/(T10+($L$3-1)*U10))))) | U9: =IF(U$1>$L$2,"",IF(U$1=$L$2,1,IF($L$2-U$1=$L$1-$M9,$L$3^($L$1-$M9),($L$3*U10*V10/(U10+($L$3-1)*V10))))) | ... DJ9: =IF(DJ$1>$L$2,"",IF(DJ$1=$L$2,1,IF($L$2-DJ$1=$L$1-$M9,$L$3^($L$1-$M9),($L$3*DJ10*DK10/(DJ10+($L$3-1)*DK10)))))
A10: =Gerenciamento!D10 -> 0 | B10: =IF(OR(I9=$L$2,H9=1+$L$1-$L$2),"",IF(A10="l",0,IF(A10="w",1,""))) -> #VALUE! | C10: =IF(OR(I9>=$L$2,D9=""),"",IF(ISERROR((1-$L$3*INDEX($N$2:$DJ$101,H9+I9+2,I9+2)/(INDEX($N$2:$DJ$101,H9+I9+2,I9+1)+($L$3-1)*(INDEX($N$2:$DJ$101,H9+I9+2,I9+2))))*$F9),$F9,(1-$L$3*INDEX($N$2:$DJ$101,H9+I9+2,I9+2)/(INDEX($N$2:$DJ$101,H9+I9+2,I9+1)+($L$3-1)*(INDEX($N$2:$DJ$101,H9+I9+2,I9+2))))*$F9)) -> #VALUE! | D10: =IF(I9>=$L$2,"",IF(B10="","",C10*($L$3-1)*B10)) -> #VALUE! | E10: =IF(B10="","",(D10-(IF((D10+F9)<=G9,D10,(G9-F9))))*(100-$L$5)/100) -> #VALUE! | F10: =IF(I9>=$L$2,"",IF(B10="","",IF(B10=0,F9-C10,IF(((F9+D10)-G9)>=0,F9+(G9-F9)+((D10-(G9-F9))*$L$5/100),F9+D10)))) -> #VALUE! | G10: =IF(F10>G9,F10,G9) -> #VALUE! | H10: =IF($L$4=0,IF(I9+B10=$L$2,0,IF(B10=0,H9+1,H9)),IF(F10>=G9,0,IF(B10=0,H9+1,H9))) -> #VALUE! | I10: =IF($L$4=0,IF(I9+B10=$L$2,0,IF(B10=1,I9+1,I9)),IF(F10>=G9,0,IF(B10=1,I9+1,I9))) -> #VALUE! | J10: =IF(B10="","",IF(ISERROR((B10+I9)/(H9+I9+1)),0,(B10+I9)/(H9+I9+1))) -> #VALUE! | M10: =IF(M9<($L$1-1),M9+1) -> FALSE | N10: =IF(N$1>$L$2,"",IF(N$1=$L$2,1,IF($L$2-N$1=$L$1-$M10,$L$3^($L$1-$M10),($L$3*N11*O11/(N11+($L$3-1)*O11))))) -> #DIV/0! | O10: =IF(O$1>$L$2,"",IF(O$1=$L$2,1,IF($L$2-O$1=$L$1-$M10,$L$3^($L$1-$M10),($L$3*O11*P11/(O11+($L$3-1)*P11))))) -> #DIV/0! | P10: =IF(P$1>$L$2,"",IF(P$1=$L$2,1,IF($L$2-P$1=$L$1-$M10,$L$3^($L$1-$M10),($L$3*P11*Q11/(P11+($L$3-1)*Q11))))) -> 1 | Q10: =IF(Q$1>$L$2,"",IF(Q$1=$L$2,1,IF($L$2-Q$1=$L$1-$M10,$L$3^($L$1-$M10),($L$3*Q11*R11/(Q11+($L$3-1)*R11))))) | R10: =IF(R$1>$L$2,"",IF(R$1=$L$2,1,IF($L$2-R$1=$L$1-$M10,$L$3^($L$1-$M10),($L$3*R11*S11/(R11+($L$3-1)*S11))))) | S10: =IF(S$1>$L$2,"",IF(S$1=$L$2,1,IF($L$2-S$1=$L$1-$M10,$L$3^($L$1-$M10),($L$3*S11*T11/(S11+($L$3-1)*T11))))) | T10: =IF(T$1>$L$2,"",IF(T$1=$L$2,1,IF($L$2-T$1=$L$1-$M10,$L$3^($L$1-$M10),($L$3*T11*U11/(T11+($L$3-1)*U11))))) | U10: =IF(U$1>$L$2,"",IF(U$1=$L$2,1,IF($L$2-U$1=$L$1-$M10,$L$3^($L$1-$M10),($L$3*U11*V11/(U11+($L$3-1)*V11))))) | ... DJ10: =IF(DJ$1>$L$2,"",IF(DJ$1=$L$2,1,IF($L$2-DJ$1=$L$1-$M10,$L$3^($L$1-$M10),($L$3*DJ11*DK11/(DJ11+($L$3-1)*DK11)))))
A11: =Gerenciamento!D11 -> 0 | B11: =IF(OR(I10=$L$2,H10=1+$L$1-$L$2),"",IF(A11="l",0,IF(A11="w",1,""))) -> #VALUE! | C11: =IF(OR(I10>=$L$2,D10=""),"",IF(ISERROR((1-$L$3*INDEX($N$2:$DJ$101,H10+I10+2,I10+2)/(INDEX($N$2:$DJ$101,H10+I10+2,I10+1)+($L$3-1)*(INDEX($N$2:$DJ$101,H10+I10+2,I10+2))))*$F10),$F10,(1-$L$3*INDEX($N$2:$DJ$101,H10+I10+2,I10+2)/(INDEX($N$2:$DJ$101,H10+I10+2,I10+1)+($L$3-1)*(INDEX($N$2:$DJ$101,H10+I10+2,I10+2))))*$F10)) -> #VALUE! | D11: =IF(I10>=$L$2,"",IF(B11="","",C11*($L$3-1)*B11)) -> #VALUE! | E11: =IF(B11="","",(D11-(IF((D11+F10)<=G10,D11,(G10-F10))))*(100-$L$5)/100) -> #VALUE! | F11: =IF(I10>=$L$2,"",IF(B11="","",IF(B11=0,F10-C11,IF(((F10+D11)-G10)>=0,F10+(G10-F10)+((D11-(G10-F10))*$L$5/100),F10+D11)))) -> #VALUE! | G11: =IF(F11>G10,F11,G10) -> #VALUE! | H11: =IF($L$4=0,IF(I10+B11=$L$2,0,IF(B11=0,H10+1,H10)),IF(F11>=G10,0,IF(B11=0,H10+1,H10))) -> #VALUE! | I11: =IF($L$4=0,IF(I10+B11=$L$2,0,IF(B11=1,I10+1,I10)),IF(F11>=G10,0,IF(B11=1,I10+1,I10))) -> #VALUE! | J11: =IF(B11="","",IF(ISERROR((B11+I10)/(H10+I10+1)),0,(B11+I10)/(H10+I10+1))) -> #VALUE! | M11: =IF(M10<($L$1-1),M10+1) -> FALSE | N11: =IF(N$1>$L$2,"",IF(N$1=$L$2,1,IF($L$2-N$1=$L$1-$M11,$L$3^($L$1-$M11),($L$3*N12*O12/(N12+($L$3-1)*O12))))) -> #DIV/0! | O11: =IF(O$1>$L$2,"",IF(O$1=$L$2,1,IF($L$2-O$1=$L$1-$M11,$L$3^($L$1-$M11),($L$3*O12*P12/(O12+($L$3-1)*P12))))) -> #DIV/0! | P11: =IF(P$1>$L$2,"",IF(P$1=$L$2,1,IF($L$2-P$1=$L$1-$M11,$L$3^($L$1-$M11),($L$3*P12*Q12/(P12+($L$3-1)*Q12))))) -> 1 | Q11: =IF(Q$1>$L$2,"",IF(Q$1=$L$2,1,IF($L$2-Q$1=$L$1-$M11,$L$3^($L$1-$M11),($L$3*Q12*R12/(Q12+($L$3-1)*R12))))) | R11: =IF(R$1>$L$2,"",IF(R$1=$L$2,1,IF($L$2-R$1=$L$1-$M11,$L$3^($L$1-$M11),($L$3*R12*S12/(R12+($L$3-1)*S12))))) | S11: =IF(S$1>$L$2,"",IF(S$1=$L$2,1,IF($L$2-S$1=$L$1-$M11,$L$3^($L$1-$M11),($L$3*S12*T12/(S12+($L$3-1)*T12))))) | T11: =IF(T$1>$L$2,"",IF(T$1=$L$2,1,IF($L$2-T$1=$L$1-$M11,$L$3^($L$1-$M11),($L$3*T12*U12/(T12+($L$3-1)*U12))))) | U11: =IF(U$1>$L$2,"",IF(U$1=$L$2,1,IF($L$2-U$1=$L$1-$M11,$L$3^($L$1-$M11),($L$3*U12*V12/(U12+($L$3-1)*V12))))) | ... DJ11: =IF(DJ$1>$L$2,"",IF(DJ$1=$L$2,1,IF($L$2-DJ$1=$L$1-$M11,$L$3^($L$1-$M11),($L$3*DJ12*DK12/(DJ12+($L$3-1)*DK12)))))
A12: =Gerenciamento!D12 -> 0 | B12: =IF(OR(I11=$L$2,H11=1+$L$1-$L$2),"",IF(A12="l",0,IF(A12="w",1,""))) -> #VALUE! | C12: =IF(OR(I11>=$L$2,D11=""),"",IF(ISERROR((1-$L$3*INDEX($N$2:$DJ$101,H11+I11+2,I11+2)/(INDEX($N$2:$DJ$101,H11+I11+2,I11+1)+($L$3-1)*(INDEX($N$2:$DJ$101,H11+I11+2,I11+2))))*$F11),$F11,(1-$L$3*INDEX($N$2:$DJ$101,H11+I11+2,I11+2)/(INDEX($N$2:$DJ$101,H11+I11+2,I11+1)+($L$3-1)*(INDEX($N$2:$DJ$101,H11+I11+2,I11+2))))*$F11)) -> #VALUE! | D12: =IF(I11>=$L$2,"",IF(B12="","",C12*($L$3-1)*B12)) -> #VALUE! | E12: =IF(B12="","",(D12-(IF((D12+F11)<=G11,D12,(G11-F11))))*(100-$L$5)/100) -> #VALUE! | F12: =IF(I11>=$L$2,"",IF(B12="","",IF(B12=0,F11-C12,IF(((F11+D12)-G11)>=0,F11+(G11-F11)+((D12-(G11-F11))*$L$5/100),F11+D12)))) -> #VALUE! | G12: =IF(F12>G11,F12,G11) -> #VALUE! | H12: =IF($L$4=0,IF(I11+B12=$L$2,0,IF(B12=0,H11+1,H11)),IF(F12>=G11,0,IF(B12=0,H11+1,H11))) -> #VALUE! | I12: =IF($L$4=0,IF(I11+B12=$L$2,0,IF(B12=1,I11+1,I11)),IF(F12>=G11,0,IF(B12=1,I11+1,I11))) -> #VALUE! | J12: =IF(B12="","",IF(ISERROR((B12+I11)/(H11+I11+1)),0,(B12+I11)/(H11+I11+1))) -> #VALUE! | M12: =IF(M11<($L$1-1),M11+1) -> FALSE | N12: =IF(N$1>$L$2,"",IF(N$1=$L$2,1,IF($L$2-N$1=$L$1-$M12,$L$3^($L$1-$M12),($L$3*N13*O13/(N13+($L$3-1)*O13))))) -> #DIV/0! | O12: =IF(O$1>$L$2,"",IF(O$1=$L$2,1,IF($L$2-O$1=$L$1-$M12,$L$3^($L$1-$M12),($L$3*O13*P13/(O13+($L$3-1)*P13))))) -> #DIV/0! | P12: =IF(P$1>$L$2,"",IF(P$1=$L$2,1,IF($L$2-P$1=$L$1-$M12,$L$3^($L$1-$M12),($L$3*P13*Q13/(P13+($L$3-1)*Q13))))) -> 1 | Q12: =IF(Q$1>$L$2,"",IF(Q$1=$L$2,1,IF($L$2-Q$1=$L$1-$M12,$L$3^($L$1-$M12),($L$3*Q13*R13/(Q13+($L$3-1)*R13))))) | R12: =IF(R$1>$L$2,"",IF(R$1=$L$2,1,IF($L$2-R$1=$L$1-$M12,$L$3^($L$1-$M12),($L$3*R13*S13/(R13+($L$3-1)*S13))))) | S12: =IF(S$1>$L$2,"",IF(S$1=$L$2,1,IF($L$2-S$1=$L$1-$M12,$L$3^($L$1-$M12),($L$3*S13*T13/(S13+($L$3-1)*T13))))) | T12: =IF(T$1>$L$2,"",IF(T$1=$L$2,1,IF($L$2-T$1=$L$1-$M12,$L$3^($L$1-$M12),($L$3*T13*U13/(T13+($L$3-1)*U13))))) | U12: =IF(U$1>$L$2,"",IF(U$1=$L$2,1,IF($L$2-U$1=$L$1-$M12,$L$3^($L$1-$M12),($L$3*U13*V13/(U13+($L$3-1)*V13))))) | ... DJ12: =IF(DJ$1>$L$2,"",IF(DJ$1=$L$2,1,IF($L$2-DJ$1=$L$1-$M12,$L$3^($L$1-$M12),($L$3*DJ13*DK13/(DJ13+($L$3-1)*DK13)))))
A13: =Gerenciamento!D13 -> 0 | B13: =IF(OR(I12=$L$2,H12=1+$L$1-$L$2),"",IF(A13="l",0,IF(A13="w",1,""))) -> #VALUE! | C13: =IF(OR(I12>=$L$2,D12=""),"",IF(ISERROR((1-$L$3*INDEX($N$2:$DJ$101,H12+I12+2,I12+2)/(INDEX($N$2:$DJ$101,H12+I12+2,I12+1)+($L$3-1)*(INDEX($N$2:$DJ$101,H12+I12+2,I12+2))))*$F12),$F12,(1-$L$3*INDEX($N$2:$DJ$101,H12+I12+2,I12+2)/(INDEX($N$2:$DJ$101,H12+I12+2,I12+1)+($L$3-1)*(INDEX($N$2:$DJ$101,H12+I12+2,I12+2))))*$F12)) -> #VALUE! | D13: =IF(I12>=$L$2,"",IF(B13="","",C13*($L$3-1)*B13)) -> #VALUE! | E13: =IF(B13="","",(D13-(IF((D13+F12)<=G12,D13,(G12-F12))))*(100-$L$5)/100) -> #VALUE! | F13: =IF(I12>=$L$2,"",IF(B13="","",IF(B13=0,F12-C13,IF(((F12+D13)-G12)>=0,F12+(G12-F12)+((D13-(G12-F12))*$L$5/100),F12+D13)))) -> #VALUE! | G13: =IF(F13>G12,F13,G12) -> #VALUE! | H13: =IF($L$4=0,IF(I12+B13=$L$2,0,IF(B13=0,H12+1,H12)),IF(F13>=G12,0,IF(B13=0,H12+1,H12))) -> #VALUE! | I13: =IF($L$4=0,IF(I12+B13=$L$2,0,IF(B13=1,I12+1,I12)),IF(F13>=G12,0,IF(B13=1,I12+1,I12))) -> #VALUE! | J13: =IF(B13="","",IF(ISERROR((B13+I12)/(H12+I12+1)),0,(B13+I12)/(H12+I12+1))) -> #VALUE! | M13: =IF(M12<($L$1-1),M12+1) -> FALSE | N13: =IF(N$1>$L$2,"",IF(N$1=$L$2,1,IF($L$2-N$1=$L$1-$M13,$L$3^($L$1-$M13),($L$3*N14*O14/(N14+($L$3-1)*O14))))) -> #DIV/0! | O13: =IF(O$1>$L$2,"",IF(O$1=$L$2,1,IF($L$2-O$1=$L$1-$M13,$L$3^($L$1-$M13),($L$3*O14*P14/(O14+($L$3-1)*P14))))) -> #DIV/0! | P13: =IF(P$1>$L$2,"",IF(P$1=$L$2,1,IF($L$2-P$1=$L$1-$M13,$L$3^($L$1-$M13),($L$3*P14*Q14/(P14+($L$3-1)*Q14))))) -> 1 | Q13: =IF(Q$1>$L$2,"",IF(Q$1=$L$2,1,IF($L$2-Q$1=$L$1-$M13,$L$3^($L$1-$M13),($L$3*Q14*R14/(Q14+($L$3-1)*R14))))) | R13: =IF(R$1>$L$2,"",IF(R$1=$L$2,1,IF($L$2-R$1=$L$1-$M13,$L$3^($L$1-$M13),($L$3*R14*S14/(R14+($L$3-1)*S14))))) | S13: =IF(S$1>$L$2,"",IF(S$1=$L$2,1,IF($L$2-S$1=$L$1-$M13,$L$3^($L$1-$M13),($L$3*S14*T14/(S14+($L$3-1)*T14))))) | T13: =IF(T$1>$L$2,"",IF(T$1=$L$2,1,IF($L$2-T$1=$L$1-$M13,$L$3^($L$1-$M13),($L$3*T14*U14/(T14+($L$3-1)*U14))))) | U13: =IF(U$1>$L$2,"",IF(U$1=$L$2,1,IF($L$2-U$1=$L$1-$M13,$L$3^($L$1-$M13),($L$3*U14*V14/(U14+($L$3-1)*V14))))) | ... DJ13: =IF(DJ$1>$L$2,"",IF(DJ$1=$L$2,1,IF($L$2-DJ$1=$L$1-$M13,$L$3^($L$1-$M13),($L$3*DJ14*DK14/(DJ14+($L$3-1)*DK14)))))
A14: =Gerenciamento!D14 -> 0 | B14: =IF(OR(I13=$L$2,H13=1+$L$1-$L$2),"",IF(A14="l",0,IF(A14="w",1,""))) -> #VALUE! | C14: =IF(OR(I13>=$L$2,D13=""),"",IF(ISERROR((1-$L$3*INDEX($N$2:$DJ$101,H13+I13+2,I13+2)/(INDEX($N$2:$DJ$101,H13+I13+2,I13+1)+($L$3-1)*(INDEX($N$2:$DJ$101,H13+I13+2,I13+2))))*$F13),$F13,(1-$L$3*INDEX($N$2:$DJ$101,H13+I13+2,I13+2)/(INDEX($N$2:$DJ$101,H13+I13+2,I13+1)+($L$3-1)*(INDEX($N$2:$DJ$101,H13+I13+2,I13+2))))*$F13)) -> #VALUE! | D14: =IF(I13>=$L$2,"",IF(B14="","",C14*($L$3-1)*B14)) -> #VALUE! | E14: =IF(B14="","",(D14-(IF((D14+F13)<=G13,D14,(G13-F13))))*(100-$L$5)/100) -> #VALUE! | F14: =IF(I13>=$L$2,"",IF(B14="","",IF(B14=0,F13-C14,IF(((F13+D14)-G13)>=0,F13+(G13-F13)+((D14-(G13-F13))*$L$5/100),F13+D14)))) -> #VALUE! | G14: =IF(F14>G13,F14,G13) -> #VALUE! | H14: =IF($L$4=0,IF(I13+B14=$L$2,0,IF(B14=0,H13+1,H13)),IF(F14>=G13,0,IF(B14=0,H13+1,H13))) -> #VALUE! | I14: =IF($L$4=0,IF(I13+B14=$L$2,0,IF(B14=1,I13+1,I13)),IF(F14>=G13,0,IF(B14=1,I13+1,I13))) -> #VALUE! | J14: =IF(B14="","",IF(ISERROR((B14+I13)/(H13+I13+1)),0,(B14+I13)/(H13+I13+1))) -> #VALUE! | M14: =IF(M13<($L$1-1),M13+1) -> FALSE | N14: =IF(N$1>$L$2,"",IF(N$1=$L$2,1,IF($L$2-N$1=$L$1-$M14,$L$3^($L$1-$M14),($L$3*N15*O15/(N15+($L$3-1)*O15))))) -> #DIV/0! | O14: =IF(O$1>$L$2,"",IF(O$1=$L$2,1,IF($L$2-O$1=$L$1-$M14,$L$3^($L$1-$M14),($L$3*O15*P15/(O15+($L$3-1)*P15))))) -> #DIV/0! | P14: =IF(P$1>$L$2,"",IF(P$1=$L$2,1,IF($L$2-P$1=$L$1-$M14,$L$3^($L$1-$M14),($L$3*P15*Q15/(P15+($L$3-1)*Q15))))) -> 1 | Q14: =IF(Q$1>$L$2,"",IF(Q$1=$L$2,1,IF($L$2-Q$1=$L$1-$M14,$L$3^($L$1-$M14),($L$3*Q15*R15/(Q15+($L$3-1)*R15))))) | R14: =IF(R$1>$L$2,"",IF(R$1=$L$2,1,IF($L$2-R$1=$L$1-$M14,$L$3^($L$1-$M14),($L$3*R15*S15/(R15+($L$3-1)*S15))))) | S14: =IF(S$1>$L$2,"",IF(S$1=$L$2,1,IF($L$2-S$1=$L$1-$M14,$L$3^($L$1-$M14),($L$3*S15*T15/(S15+($L$3-1)*T15))))) | T14: =IF(T$1>$L$2,"",IF(T$1=$L$2,1,IF($L$2-T$1=$L$1-$M14,$L$3^($L$1-$M14),($L$3*T15*U15/(T15+($L$3-1)*U15))))) | U14: =IF(U$1>$L$2,"",IF(U$1=$L$2,1,IF($L$2-U$1=$L$1-$M14,$L$3^($L$1-$M14),($L$3*U15*V15/(U15+($L$3-1)*V15))))) | ... DJ14: =IF(DJ$1>$L$2,"",IF(DJ$1=$L$2,1,IF($L$2-DJ$1=$L$1-$M14,$L$3^($L$1-$M14),($L$3*DJ15*DK15/(DJ15+($L$3-1)*DK15)))))
A15: =Gerenciamento!D15 -> 0 | B15: =IF(OR(I14=$L$2,H14=1+$L$1-$L$2),"",IF(A15="l",0,IF(A15="w",1,""))) -> #VALUE! | C15: =IF(OR(I14>=$L$2,D14=""),"",IF(ISERROR((1-$L$3*INDEX($N$2:$DJ$101,H14+I14+2,I14+2)/(INDEX($N$2:$DJ$101,H14+I14+2,I14+1)+($L$3-1)*(INDEX($N$2:$DJ$101,H14+I14+2,I14+2))))*$F14),$F14,(1-$L$3*INDEX($N$2:$DJ$101,H14+I14+2,I14+2)/(INDEX($N$2:$DJ$101,H14+I14+2,I14+1)+($L$3-1)*(INDEX($N$2:$DJ$101,H14+I14+2,I14+2))))*$F14)) -> #VALUE! | D15: =IF(I14>=$L$2,"",IF(B15="","",C15*($L$3-1)*B15)) -> #VALUE! | E15: =IF(B15="","",(D15-(IF((D15+F14)<=G14,D15,(G14-F14))))*(100-$L$5)/100) -> #VALUE! | F15: =IF(I14>=$L$2,"",IF(B15="","",IF(B15=0,F14-C15,IF(((F14+D15)-G14)>=0,F14+(G14-F14)+((D15-(G14-F14))*$L$5/100),F14+D15)))) -> #VALUE! | G15: =IF(F15>G14,F15,G14) -> #VALUE! | H15: =IF($L$4=0,IF(I14+B15=$L$2,0,IF(B15=0,H14+1,H14)),IF(F15>=G14,0,IF(B15=0,H14+1,H14))) -> #VALUE! | I15: =IF($L$4=0,IF(I14+B15=$L$2,0,IF(B15=1,I14+1,I14)),IF(F15>=G14,0,IF(B15=1,I14+1,I14))) -> #VALUE! | J15: =IF(B15="","",IF(ISERROR((B15+I14)/(H14+I14+1)),0,(B15+I14)/(H14+I14+1))) -> #VALUE! | M15: =IF(M14<($L$1-1),M14+1) -> FALSE | N15: =IF(N$1>$L$2,"",IF(N$1=$L$2,1,IF($L$2-N$1=$L$1-$M15,$L$3^($L$1-$M15),($L$3*N16*O16/(N16+($L$3-1)*O16))))) -> #DIV/0! | O15: =IF(O$1>$L$2,"",IF(O$1=$L$2,1,IF($L$2-O$1=$L$1-$M15,$L$3^($L$1-$M15),($L$3*O16*P16/(O16+($L$3-1)*P16))))) -> #DIV/0! | P15: =IF(P$1>$L$2,"",IF(P$1=$L$2,1,IF($L$2-P$1=$L$1-$M15,$L$3^($L$1-$M15),($L$3*P16*Q16/(P16+($L$3-1)*Q16))))) -> 1 | Q15: =IF(Q$1>$L$2,"",IF(Q$1=$L$2,1,IF($L$2-Q$1=$L$1-$M15,$L$3^($L$1-$M15),($L$3*Q16*R16/(Q16+($L$3-1)*R16))))) | R15: =IF(R$1>$L$2,"",IF(R$1=$L$2,1,IF($L$2-R$1=$L$1-$M15,$L$3^($L$1-$M15),($L$3*R16*S16/(R16+($L$3-1)*S16))))) | S15: =IF(S$1>$L$2,"",IF(S$1=$L$2,1,IF($L$2-S$1=$L$1-$M15,$L$3^($L$1-$M15),($L$3*S16*T16/(S16+($L$3-1)*T16))))) | T15: =IF(T$1>$L$2,"",IF(T$1=$L$2,1,IF($L$2-T$1=$L$1-$M15,$L$3^($L$1-$M15),($L$3*T16*U16/(T16+($L$3-1)*U16))))) | U15: =IF(U$1>$L$2,"",IF(U$1=$L$2,1,IF($L$2-U$1=$L$1-$M15,$L$3^($L$1-$M15),($L$3*U16*V16/(U16+($L$3-1)*V16))))) | ... DJ15: =IF(DJ$1>$L$2,"",IF(DJ$1=$L$2,1,IF($L$2-DJ$1=$L$1-$M15,$L$3^($L$1-$M15),($L$3*DJ16*DK16/(DJ16+($L$3-1)*DK16)))))
A16: =Gerenciamento!D16 -> 0 | B16: =IF(OR(I15=$L$2,H15=1+$L$1-$L$2),"",IF(A16="l",0,IF(A16="w",1,""))) -> #VALUE! | C16: =IF(OR(I15>=$L$2,D15=""),"",IF(ISERROR((1-$L$3*INDEX($N$2:$DJ$101,H15+I15+2,I15+2)/(INDEX($N$2:$DJ$101,H15+I15+2,I15+1)+($L$3-1)*(INDEX($N$2:$DJ$101,H15+I15+2,I15+2))))*$F15),$F15,(1-$L$3*INDEX($N$2:$DJ$101,H15+I15+2,I15+2)/(INDEX($N$2:$DJ$101,H15+I15+2,I15+1)+($L$3-1)*(INDEX($N$2:$DJ$101,H15+I15+2,I15+2))))*$F15)) -> #VALUE! | D16: =IF(I15>=$L$2,"",IF(B16="","",C16*($L$3-1)*B16)) -> #VALUE! | E16: =IF(B16="","",(D16-(IF((D16+F15)<=G15,D16,(G15-F15))))*(100-$L$5)/100) -> #VALUE! | F16: =IF(I15>=$L$2,"",IF(B16="","",IF(B16=0,F15-C16,IF(((F15+D16)-G15)>=0,F15+(G15-F15)+((D16-(G15-F15))*$L$5/100),F15+D16)))) -> #VALUE! | G16: =IF(F16>G15,F16,G15) -> #VALUE! | H16: =IF($L$4=0,IF(I15+B16=$L$2,0,IF(B16=0,H15+1,H15)),IF(F16>=G15,0,IF(B16=0,H15+1,H15))) -> #VALUE! | I16: =IF($L$4=0,IF(I15+B16=$L$2,0,IF(B16=1,I15+1,I15)),IF(F16>=G15,0,IF(B16=1,I15+1,I15))) -> #VALUE! | J16: =IF(B16="","",IF(ISERROR((B16+I15)/(H15+I15+1)),0,(B16+I15)/(H15+I15+1))) -> #VALUE! | M16: =IF(M15<($L$1-1),M15+1) -> FALSE | N16: =IF(N$1>$L$2,"",IF(N$1=$L$2,1,IF($L$2-N$1=$L$1-$M16,$L$3^($L$1-$M16),($L$3*N17*O17/(N17+($L$3-1)*O17))))) -> #DIV/0! | O16: =IF(O$1>$L$2,"",IF(O$1=$L$2,1,IF($L$2-O$1=$L$1-$M16,$L$3^($L$1-$M16),($L$3*O17*P17/(O17+($L$3-1)*P17))))) -> #DIV/0! | P16: =IF(P$1>$L$2,"",IF(P$1=$L$2,1,IF($L$2-P$1=$L$1-$M16,$L$3^($L$1-$M16),($L$3*P17*Q17/(P17+($L$3-1)*Q17))))) -> 1 | Q16: =IF(Q$1>$L$2,"",IF(Q$1=$L$2,1,IF($L$2-Q$1=$L$1-$M16,$L$3^($L$1-$M16),($L$3*Q17*R17/(Q17+($L$3-1)*R17))))) | R16: =IF(R$1>$L$2,"",IF(R$1=$L$2,1,IF($L$2-R$1=$L$1-$M16,$L$3^($L$1-$M16),($L$3*R17*S17/(R17+($L$3-1)*S17))))) | S16: =IF(S$1>$L$2,"",IF(S$1=$L$2,1,IF($L$2-S$1=$L$1-$M16,$L$3^($L$1-$M16),($L$3*S17*T17/(S17+($L$3-1)*T17))))) | T16: =IF(T$1>$L$2,"",IF(T$1=$L$2,1,IF($L$2-T$1=$L$1-$M16,$L$3^($L$1-$M16),($L$3*T17*U17/(T17+($L$3-1)*U17))))) | U16: =IF(U$1>$L$2,"",IF(U$1=$L$2,1,IF($L$2-U$1=$L$1-$M16,$L$3^($L$1-$M16),($L$3*U17*V17/(U17+($L$3-1)*V17))))) | ... DJ16: =IF(DJ$1>$L$2,"",IF(DJ$1=$L$2,1,IF($L$2-DJ$1=$L$1-$M16,$L$3^($L$1-$M16),($L$3*DJ17*DK17/(DJ17+($L$3-1)*DK17)))))
A17: =Gerenciamento!D17 -> 0 | B17: =IF(OR(I16=$L$2,H16=1+$L$1-$L$2),"",IF(A17="l",0,IF(A17="w",1,""))) -> #VALUE! | C17: =IF(OR(I16>=$L$2,D16=""),"",IF(ISERROR((1-$L$3*INDEX($N$2:$DJ$101,H16+I16+2,I16+2)/(INDEX($N$2:$DJ$101,H16+I16+2,I16+1)+($L$3-1)*(INDEX($N$2:$DJ$101,H16+I16+2,I16+2))))*$F16),$F16,(1-$L$3*INDEX($N$2:$DJ$101,H16+I16+2,I16+2)/(INDEX($N$2:$DJ$101,H16+I16+2,I16+1)+($L$3-1)*(INDEX($N$2:$DJ$101,H16+I16+2,I16+2))))*$F16)) -> #VALUE! | D17: =IF(I16>=$L$2,"",IF(B17="","",C17*($L$3-1)*B17)) -> #VALUE! | E17: =IF(B17="","",(D17-(IF((D17+F16)<=G16,D17,(G16-F16))))*(100-$L$5)/100) -> #VALUE! | F17: =IF(I16>=$L$2,"",IF(B17="","",IF(B17=0,F16-C17,IF(((F16+D17)-G16)>=0,F16+(G16-F16)+((D17-(G16-F16))*$L$5/100),F16+D17)))) -> #VALUE! | G17: =IF(F17>G16,F17,G16) -> #VALUE! | H17: =IF($L$4=0,IF(I16+B17=$L$2,0,IF(B17=0,H16+1,H16)),IF(F17>=G16,0,IF(B17=0,H16+1,H16))) -> #VALUE! | I17: =IF($L$4=0,IF(I16+B17=$L$2,0,IF(B17=1,I16+1,I16)),IF(F17>=G16,0,IF(B17=1,I16+1,I16))) -> #VALUE! | J17: =IF(B17="","",IF(ISERROR((B17+I16)/(H16+I16+1)),0,(B17+I16)/(H16+I16+1))) -> #VALUE! | M17: =IF(M16<($L$1-1),M16+1) -> FALSE | N17: =IF(N$1>$L$2,"",IF(N$1=$L$2,1,IF($L$2-N$1=$L$1-$M17,$L$3^($L$1-$M17),($L$3*N18*O18/(N18+($L$3-1)*O18))))) -> #DIV/0! | O17: =IF(O$1>$L$2,"",IF(O$1=$L$2,1,IF($L$2-O$1=$L$1-$M17,$L$3^($L$1-$M17),($L$3*O18*P18/(O18+($L$3-1)*P18))))) -> #DIV/0! | P17: =IF(P$1>$L$2,"",IF(P$1=$L$2,1,IF($L$2-P$1=$L$1-$M17,$L$3^($L$1-$M17),($L$3*P18*Q18/(P18+($L$3-1)*Q18))))) -> 1 | Q17: =IF(Q$1>$L$2,"",IF(Q$1=$L$2,1,IF($L$2-Q$1=$L$1-$M17,$L$3^($L$1-$M17),($L$3*Q18*R18/(Q18+($L$3-1)*R18))))) | R17: =IF(R$1>$L$2,"",IF(R$1=$L$2,1,IF($L$2-R$1=$L$1-$M17,$L$3^($L$1-$M17),($L$3*R18*S18/(R18+($L$3-1)*S18))))) | S17: =IF(S$1>$L$2,"",IF(S$1=$L$2,1,IF($L$2-S$1=$L$1-$M17,$L$3^($L$1-$M17),($L$3*S18*T18/(S18+($L$3-1)*T18))))) | T17: =IF(T$1>$L$2,"",IF(T$1=$L$2,1,IF($L$2-T$1=$L$1-$M17,$L$3^($L$1-$M17),($L$3*T18*U18/(T18+($L$3-1)*U18))))) | U17: =IF(U$1>$L$2,"",IF(U$1=$L$2,1,IF($L$2-U$1=$L$1-$M17,$L$3^($L$1-$M17),($L$3*U18*V18/(U18+($L$3-1)*V18))))) | ... DJ17: =IF(DJ$1>$L$2,"",IF(DJ$1=$L$2,1,IF($L$2-DJ$1=$L$1-$M17,$L$3^($L$1-$M17),($L$3*DJ18*DK18/(DJ18+($L$3-1)*DK18)))))
... A101: =Gerenciamento!D101 -> 0 | B101: =IF(OR(I100=$L$2,H100=1+$L$1-$L$2),"",IF(A101="l",0,IF(A101="w",1,""))) -> #VALUE! | C101: =IF(OR(I100>=$L$2,D100=""),"",IF(ISERROR((1-$L$3*INDEX($N$2:$DJ$101,H100+I100+2,I100+2)/(INDEX($N$2:$DJ$101,H100+I100+2,I100+1)+($L$3-1)*(INDEX($N$2:$DJ$101,H100+I100+2,I100+2))))*$F100),$F100,(1-$L$3*INDEX($N$2:$DJ$101,H100+I100+2,I100+2)/(INDEX($N$2:$DJ$101,H100+I100+2,I100+1)+($L$3-1)*(INDEX($N$2:$DJ$101,H100+I100+2,I100+2))))*$F100)) -> #VALUE! | D101: =IF(I100>=$L$2,"",IF(B101="","",C101*($L$3-1)*B101)) -> #VALUE! | E101: =IF(B101="","",(D101-(IF((D101+F100)<=G100,D101,(G100-F100))))*(100-$L$5)/100) -> #VALUE! | F101: =IF(I100>=$L$2,"",IF(B101="","",IF(B101=0,F100-C101,IF(((F100+D101)-G100)>=0,F100+(G100-F100)+((D101-(G100-F100))*$L$5/100),F100+D101)))) -> #VALUE! | G101: =IF(F101>G100,F101,G100) -> #VALUE! | H101: =IF($L$4=0,IF(I100+B101=$L$2,0,IF(B101=0,H100+1,H100)),IF(F101>=G100,0,IF(B101=0,H100+1,H100))) -> #VALUE! | I101: =IF($L$4=0,IF(I100+B101=$L$2,0,IF(B101=1,I100+1,I100)),IF(F101>=G100,0,IF(B101=1,I100+1,I100))) -> #VALUE! | J101: =IF(B101="","",IF(ISERROR((B101+I100)/(H100+I100+1)),0,(B101+I100)/(H100+I100+1))) -> #VALUE! | M101: =IF(M100<($L$1-1),M100+1) -> FALSE | N101: =IF(N$1>$L$2,"",IF(N$1=$L$2,1,IF($L$2-N$1=$L$1-$M101,$L$3^($L$1-$M101),($L$3*N102*O102/(N102+($L$3-1)*O102))))) -> #DIV/0! | O101: =IF(O$1>$L$2,"",IF(O$1=$L$2,1,IF($L$2-O$1=$L$1-$M101,$L$3^($L$1-$M101),($L$3*O102*P102/(O102+($L$3-1)*P102))))) -> #DIV/0! | P101: =IF(P$1>$L$2,"",IF(P$1=$L$2,1,IF($L$2-P$1=$L$1-$M101,$L$3^($L$1-$M101),($L$3*P102*Q102/(P102+($L$3-1)*Q102))))) -> 1 | Q101: =IF(Q$1>$L$2,"",IF(Q$1=$L$2,1,IF($L$2-Q$1=$L$1-$M101,$L$3^($L$1-$M101),($L$3*Q102*R102/(Q102+($L$3-1)*R102))))) | R101: =IF(R$1>$L$2,"",IF(R$1=$L$2,1,IF($L$2-R$1=$L$1-$M101,$L$3^($L$1-$M101),($L$3*R102*S102/(R102+($L$3-1)*S102))))) | S101: =IF(S$1>$L$2,"",IF(S$1=$L$2,1,IF($L$2-S$1=$L$1-$M101,$L$3^($L$1-$M101),($L$3*S102*T102/(S102+($L$3-1)*T102))))) | T101: =IF(T$1>$L$2,"",IF(T$1=$L$2,1,IF($L$2-T$1=$L$1-$M101,$L$3^($L$1-$M101),($L$3*T102*U102/(T102+($L$3-1)*U102))))) | U101: =IF(U$1>$L$2,"",IF(U$1=$L$2,1,IF($L$2-U$1=$L$1-$M101,$L$3^($L$1-$M101),($L$3*U102*V102/(U102+($L$3-1)*V102))))) | ... DJ101: =IF(DJ$1>$L$2,"",IF(DJ$1=$L$2,1,IF($L$2-DJ$1=$L$1-$M101,$L$3^($L$1-$M101),($L$3*DJ102*DK102/(DJ102+($L$3-1)*DK102)))))
